Workbook

Sheet Carteiras
B2: Edite os campos amarelos com o percentual do investimento na carteira:
K3: Indicadores | L3: DÓLAR | M3: CDI | N3: IVVB11 | O3: BOVA11 | P3: SMAL11 | Q3: Conservadora | R3: Moderada | S3: Agressiva
B4: Conservador | E4: Moderado | H4: Agressivo | K4: =Dados!X5 -> Retorno Total | L4: =Dados!Y5 -> 0.065246386 | M4: =Dados!Z5 -> 0.46195128 | N4: =Dados!AA5 -> 1.8400345 | O4: =Dados!AB5 -> 1.8781913 | P4: =Dados!AC5 -> 2.5956434 | Q4: =Dados!AD5 -> 0.58471526 | R4: =Dados!AE5 -> 1.1474166 | S4: =Dados!AF5 -> 1.552318
B5: DÓLAR | C5: 0 | E5: DÓLAR | F5: 0.05 | H5: DÓLAR | I5: 0.1 | K5: =Dados!X6 -> Retorno Médio | L5: =Dados!Y6 -> 0.025134207 | M5: =Dados!Z6 -> 0.072690336 | N5: =Dados!AA6 -> 0.2335636 | O5: =Dados!AB6 -> 0.25601544 | P5: =Dados!AC6 -> 0.31876947 | Q5: =Dados!AD6 -> 0.088857543 | R5: =Dados!AE6 -> 0.15469162 | S5: =Dados!AF6 -> 0.19454107
B6: CDI | C6: 0.9 | E6: CDI | F6: 0.5 | H6: CDI | I6: 0.25 | K6: =Dados!X7 -> Retorno Composto | L6: =Dados!Y7 -> 0.011737169 | M6: =Dados!Z7 -> 0.072628051 | N6: =Dados!AA7 -> 0.21252448 | O6: =Dados!AB7 -> 0.21551564 | P6: =Dados!AC7 -> 0.26649918 | Q6: =Dados!AD7 -> 0.08871467 | R6: =Dados!AE7 -> 0.15153424 | S6: =Dados!AF7 -> 0.18884825
B7: IVVB11 | C7: 0.05 | E7: IVVB11 | F7: 0.15 | H7: IVVB11 | I7: 0.3 | K7: =Dados!X8 -> Risco | L7: =Dados!Y8 -> 0.16361412 | M7: =Dados!Z8 -> 0.010928306 | N7: =Dados!AA8 -> 0.18958047 | O7: =Dados!AB8 -> 0.25261121 | P7: =Dados!AC8 -> 0.27495051 | Q7: =Dados!AD8 -> 0.016421044 | R7: =Dados!AE8 -> 0.074695573 | S7: =Dados!AF8 -> 0.099252936
B8: BOVA11 | C8: 0.05 | E8: BOVA11 | F8: 0.15 | H8: BOVA11 | I8: 0.05 | K8: =Dados!X9 -> Sharpe | L8: =Dados!Y9 -> -0.37216154 | M8: =Dados!Z9 -> 0 | N8: =Dados!AA9 -> 0.73792636 | O8: =Dados!AB9 -> 0.56564232 | P8: =Dados!AC9 -> 0.70511281 | Q8: =Dados!AD9 -> 0.97963432 | R8: =Dados!AE9 -> 1.0563703 | S8: =Dados!AF9 -> 1.1709497
B9: SMAL11 | C9: 0 | E9: SMAL11 | F9: 0.15 | H9: SMAL11 | I9: 0.3 | K9: =Dados!X10 -> Retorno Máximo | L9: =Dados!Y10 -> 0.1578 | M9: =Dados!Z10 -> 0.0116 | N9: =Dados!AA10 -> 0.179 | O9: =Dados!AB10 -> 0.1735 | P9: =Dados!AC10 -> 0.1753 | Q9: =Dados!AD10 -> 0.018585 | R9: =Dados!AE10 -> 0.070205 | S9: =Dados!AF10 -> 0.109985
B10: Total | C10: =SUM(C5:C9) -> 1 | E10: Total | F10: =SUM(F5:F9) -> 1 | H10: Total | I10: =SUM(I5:I9) -> 1 | K10: =Dados!X11 -> Retorno Mínimo | L10: =Dados!Y11 -> -0.1204 | M10: =Dados!Z11 -> 0.0013 | N10: =Dados!AA11 -> -0.1382 | O10: =Dados!AB11 -> -0.3106 | P10: =Dados!AC11 -> -0.3748 | Q10: =Dados!AD11 -> -0.01139 | R10: =Dados!AE11 -> -0.08998 | S10: =Dados!AF11 -> -0.10486
M15: DÓLAR | N15: CDI | O15: IVVB11 | P15: BOVA11 | Q15: SMAL11
L16: C | M16: =IFERROR(INDEX($B$5:$C$9,MATCH(M$15,$B$5:$B$9,0),2),"-") -> 0 | N16: =IFERROR(INDEX($B$5:$C$9,MATCH(N$15,$B$5:$B$9,0),2),"-") -> 0.9 | O16: =IFERROR(INDEX($B$5:$C$9,MATCH(O$15,$B$5:$B$9,0),2),"-") -> 0.05 | P16: =IFERROR(INDEX($B$5:$C$9,MATCH(P$15,$B$5:$B$9,0),2),"-") -> 0.05 | Q16: =IFERROR(INDEX($B$5:$C$9,MATCH(Q$15,$B$5:$B$9,0),2),"-") -> 0
L17: M | M17: =IFERROR(INDEX($E$5:$F$9,MATCH(M$15,$E$5:$E$9,0),2),"-") -> 0.05 | N17: =IFERROR(INDEX($E$5:$F$9,MATCH(N$15,$E$5:$E$9,0),2),"-") -> 0.5 | O17: =IFERROR(INDEX($E$5:$F$9,MATCH(O$15,$E$5:$E$9,0),2),"-") -> 0.15 | P17: =IFERROR(INDEX($E$5:$F$9,MATCH(P$15,$E$5:$E$9,0),2),"-") -> 0.15 | Q17: =IFERROR(INDEX($E$5:$F$9,MATCH(Q$15,$E$5:$E$9,0),2),"-") -> 0.15
L18: A | M18: =IFERROR(INDEX($H$5:$I$9,MATCH(M$15,$H$5:$H$9,0),2),"-") -> 0.1 | N18: =IFERROR(INDEX($H$5:$I$9,MATCH(N$15,$H$5:$H$9,0),2),"-") -> 0.25 | O18: =IFERROR(INDEX($H$5:$I$9,MATCH(O$15,$H$5:$H$9,0),2),"-") -> 0.3 | P18: =IFERROR(INDEX($H$5:$I$9,MATCH(P$15,$H$5:$H$9,0),2),"-") -> 0.05 | Q18: =IFERROR(INDEX($H$5:$I$9,MATCH(Q$15,$H$5:$H$9,0),2),"-") -> 0.3

Sheet Dados
A2: 1 | B2: Dados | K2: 2 | L2: Retorno Ano-a-Ano | W2: 3 | X2: Estatísticas | AI2: 4 | AJ2: Dados em Evolução de 100 | AU2: 5 | AV2: Retorno em 12 meses corridos | BG2: 6 | BH2: Risco em 12 meses corridos
A4: Mês | B4: DÓLAR | C4: CDI | D4: IVVB11 | E4: BOVA11 | F4: SMAL11 | G4: Conservadora | H4: Moderada | I4: Agressiva | L4: Ano | M4: DÓLAR | N4: CDI | O4: IVVB11 | P4: BOVA11 | Q4: SMAL11 | R4: Conservadora | S4: Moderada | T4: Agressiva | X4: Indicadores | Y4: DÓLAR | Z4: CDI | AA4: IVVB11 | AB4: BOVA11 | AC4: SMAL11 | AD4: Conservadora | AE4: Moderada | AF4: Agressiva | AJ4: Mês | AK4: DÓLAR | AL4: CDI | AM4: IVVB11 | AN4: BOVA11 | AO4: SMAL11 | AP4: Conservadora | AQ4: Moderada | AR4: Agressiva | AV4: Mês | AW4: DÓLAR | AX4: CDI | AY4: IVVB11 | AZ4: BOVA11 | BA4: SMAL11 | BB4: Conservadora | BC4: Moderada | BD4: Agressiva | BH4: Mês | BI4: DÓLAR | BJ4: CDI | BK4: IVVB11 | BL4: BOVA11 | BM4: SMAL11 | BN4: Conservadora | BO4: Moderada | BP4: Agressiva
A5: 42370 | B5: 0.0019 | C5: 0.0105 | D5: -0.0544 | E5: -0.0698 | F5: -0.092 | G5: =SUMPRODUCT($B5:$F5,Carteiras!$M$16:$Q$16) -> 0.00324 | H5: =SUMPRODUCT($B5:$F5,Carteiras!$M$17:$Q$17) -> -0.027085 | I5: =SUMPRODUCT($B5:$F5,Carteiras!$M$18:$Q$18) -> -0.044595 | L5: 2016 | M5: {=SUMPRODUCT(PRODUCT(B5:B16+1)-1)} -> -0.25678815 | N5: =SUMPRODUCT(PRODUCT(C5:C16+1)-1) -> 0.13668034 | O5: {=SUMPRODUCT(PRODUCT(D5:D16+1)-1)} -> -0.093444329 | P5: {=SUMPRODUCT(PRODUCT(E5:E16+1)-1)} -> 0.38260406 | Q5: {=SUMPRODUCT(PRODUCT(F5:F16+1)-1)} -> 0.3025027 | R5: =SUMPRODUCT(PRODUCT(G5:G16+1)-1) -> 0.13816719 | S5: =SUMPRODUCT(PRODUCT(H5:H16+1)-1) -> 0.1446068 | T5: =SUMPRODUCT(PRODUCT(I5:I16+1)-1) -> 0.088208045 | X5: Retorno Total | Y5: =SUMPRODUCT(PRODUCT(B5:B112+1)-1) -> 0.065246386 | Z5: =SUMPRODUCT(PRODUCT(C5:C112+1)-1) -> 0.46195128 | AA5: =SUMPRODUCT(PRODUCT(D5:D112+1)-1) -> 1.8400345 | AB5: =SUMPRODUCT(PRODUCT(E5:E112+1)-1) -> 1.8781913 | AC5: =SUMPRODUCT(PRODUCT(F5:F112+1)-1) -> 2.5956434 | AD5: =SUMPRODUCT(PRODUCT(G5:G112+1)-1) -> 0.58471526 | AE5: =SUMPRODUCT(PRODUCT(H5:H112+1)-1) -> 1.1474166 | AF5: =SUMPRODUCT(PRODUCT(I5:I112+1)-1) -> 1.552318 | AJ5: 42370 | AK5: 100 | AL5: 100 | AM5: 100 | AN5: 100 | AO5: 100 | AP5: 100 | AQ5: 100 | AR5: 100 | AV5: 42705 | AW5: {=SUMPRODUCT(PRODUCT(B5:B16+1)-1)} -> -0.25678815 | AX5: =SUMPRODUCT(PRODUCT(C5:C16+1)-1) -> 0.13668034 | AY5: =SUMPRODUCT(PRODUCT(D5:D16+1)-1) -> -0.093444329 | AZ5: =SUMPRODUCT(PRODUCT(E5:E16+1)-1) -> 0.38260406 | BA5: =SUMPRODUCT(PRODUCT(F5:F16+1)-1) -> 0.3025027 | BB5: =SUMPRODUCT(PRODUCT(G5:G16+1)-1) -> 0.13816719 | BC5: =SUMPRODUCT(PRODUCT(H5:H16+1)-1) -> 0.1446068 | BD5: =SUMPRODUCT(PRODUCT(I5:I16+1)-1) -> 0.088208045 | BH5: 42705 | BI5: =STDEV(B5:B16)*SQRT(12) -> 0.18402429 | BJ5: =STDEV(C5:C16)*SQRT(12) -> 0.0019164361 | BK5: =STDEV(D5:D16)*SQRT(12) -> 0.20182319 | BL5: =STDEV(E5:E16)*SQRT(12) -> 0.28599003 | BM5: =STDEV(F5:F16)*SQRT(12) -> 0.26379894 | BN5: =STDEV(G5:G16)*SQRT(12) -> 0.01411748 | BO5: =STDEV(H5:H16)*SQRT(12) -> 0.072483124 | BP5: =STDEV(I5:I16)*SQRT(12) -> 0.091206379
A6: 42401 | B6: -0.0025 | C6: 0.01 | D6: 0.0098 | E6: 0.0577 | F6: 0.0514 | G6: =SUMPRODUCT($B6:$F6,Carteiras!$M$16:$Q$16) -> 0.012375 | H6: =SUMPRODUCT($B6:$F6,Carteiras!$M$17:$Q$17) -> 0.02271 | I6: =SUMPRODUCT($B6:$F6,Carteiras!$M$18:$Q$18) -> 0.023495 | L6: 2017 | M6: {=SUMPRODUCT(PRODUCT(B17:B28+1)-1)} -> -0.050479163 | N6: =SUMPRODUCT(PRODUCT(C17:C28+1)-1) -> 0.099666687 | O6: {=SUMPRODUCT(PRODUCT(D17:D28+1)-1)} -> 0.23152637 | P6: {=SUMPRODUCT(PRODUCT(E17:E28+1)-1)} -> 0.26753542 | Q6: {=SUMPRODUCT(PRODUCT(F17:F28+1)-1)} -> 0.49624004 | R6: =SUMPRODUCT(PRODUCT(G17:G28+1)-1) -> 0.11456864 | S6: =SUMPRODUCT(PRODUCT(H17:H28+1)-1) -> 0.19242156 | T6: =SUMPRODUCT(PRODUCT(I17:I28+1)-1) -> 0.24519836 | X6: Retorno Médio | Y6: =(1+AVERAGE(B5:B1011))^12-1 -> 0.025134207 | Z6: =(1+AVERAGE(C5:C1011))^12-1 -> 0.072690336 | AA6: =(1+AVERAGE(D5:D1011))^12-1 -> 0.2335636 | AB6: =(1+AVERAGE(E5:E1011))^12-1 -> 0.25601544 | AC6: =(1+AVERAGE(F5:F1011))^12-1 -> 0.31876947 | AD6: =(1+AVERAGE(G5:G1011))^12-1 -> 0.088857543 | AE6: =(1+AVERAGE(H5:H1011))^12-1 -> 0.15469162 | AF6: =(1+AVERAGE(I5:I1011))^12-1 -> 0.19454107 | AJ6: 42401 | AK6: =AK5*(1+B5) -> 100.19 | AL6: =AL5*(1+C5) -> 101.05 | AM6: =AM5*(1+D5) -> 94.56 | AN6: =AN5*(1+E5) -> 93.02 | AO6: =AO5*(1+F5) -> 90.8 | AP6: =AP5*(1+G5) -> 100.324 | AQ6: =AQ5*(1+H5) -> 97.2915 | AR6: =AR5*(1+I5) -> 95.5405 | AV6: 42737 | AW6: =SUMPRODUCT(PRODUCT(B6:B17+1)-1) -> -0.28831475 | AX6: =SUMPRODUCT(PRODUCT(C6:C17+1)-1) -> 0.1370178 | AY6: =SUMPRODUCT(PRODUCT(D6:D17+1)-1) -> -0.061519304 | AZ6: =SUMPRODUCT(PRODUCT(E6:E17+1)-1) -> 0.59232824 | BA6: =SUMPRODUCT(PRODUCT(F6:F17+1)-1) -> 0.60417265 | BB6: =SUMPRODUCT(PRODUCT(G6:G17+1)-1) -> 0.14836627 | BC6: =SUMPRODUCT(PRODUCT(H6:H17+1)-1) -> 0.21017156 | BD6: =SUMPRODUCT(PRODUCT(I6:I17+1)-1) -> 0.17472662 | BH6: 42737 | BI6: =STDEV(B6:B17)*SQRT(12) -> 0.18263441 | BJ6: =STDEV(C6:C17)*SQRT(12) -> 0.0019 | BK6: =STDEV(D6:D17)*SQRT(12) -> 0.19587596 | BL6: =STDEV(E6:E17)*SQRT(12) -> 0.2661813 | BM6: =STDEV(F6:F17)*SQRT(12) -> 0.24533542 | BN6: =STDEV(G6:G17)*SQRT(12) -> 0.011438545 | BO6: =STDEV(H6:H17)*SQRT(12) -> 0.060547124 | BP6: =STDEV(I6:I17)*SQRT(12) -> 0.07398722
A7: 42430 | B7: -0.1112 | C7: 0.01 | D7: -0.0484 | E7: 0.1735 | F7: 0.116 | G7: =SUMPRODUCT($B7:$F7,Carteiras!$M$16:$Q$16) -> 0.015255 | H7: =SUMPRODUCT($B7:$F7,Carteiras!$M$17:$Q$17) -> 0.035605 | I7: =SUMPRODUCT($B7:$F7,Carteiras!$M$18:$Q$18) -> 0.020335 | L7: 2018 | M7: {=SUMPRODUCT(PRODUCT(B29:B40+1)-1)} -> 0.12774147 | N7: =SUMPRODUCT(PRODUCT(C29:C40+1)-1) -> 0.064109288 | O7: {=SUMPRODUCT(PRODUCT(D29:D40+1)-1)} -> 0.09775546 | P7: {=SUMPRODUCT(PRODUCT(E29:E40+1)-1)} -> 0.14605036 | Q7: {=SUMPRODUCT(PRODUCT(F29:F40+1)-1)} -> 0.075305498 | R7: =SUMPRODUCT(PRODUCT(G29:G40+1)-1) -> 0.072481117 | S7: =SUMPRODUCT(PRODUCT(H29:H40+1)-1) -> 0.097214674 | T7: =SUMPRODUCT(PRODUCT(I29:I40+1)-1) -> 0.10436174 | X7: Retorno Composto | Y7: =(1+Y5)^(12/COUNTA(B5:B1011))-1 -> 0.011737169 | Z7: =(1+Z5)^(12/COUNTA(C5:C1011))-1 -> 0.072628051 | AA7: =(1+AA5)^(12/COUNTA(D5:D1011))-1 -> 0.21252448 | AB7: =(1+AB5)^(12/COUNTA(E5:E1011))-1 -> 0.21551564 | AC7: =(1+AC5)^(12/COUNTA(F5:F1011))-1 -> 0.26649918 | AD7: =(1+AD5)^(12/COUNTA(G5:G1011))-1 -> 0.08871467 | AE7: =(1+AE5)^(12/COUNTA(H5:H1011))-1 -> 0.15153424 | AF7: =(1+AF5)^(12/COUNTA(I5:I1011))-1 -> 0.18884825 | AJ7: 42430 | AK7: =AK6*(1+B6) -> 99.939525 | AL7: =AL6*(1+C6) -> 102.0605 | AM7: =AM6*(1+D6) -> 95.486688 | AN7: =AN6*(1+E6) -> 98.387254 | AO7: =AO6*(1+F6) -> 95.46712 | AP7: =AP6*(1+G6) -> 101.56551 | AQ7: =AQ6*(1+H6) -> 99.50099 | AR7: =AR6*(1+I6) -> 97.785224 | AV7: 42767 | AW7: =SUMPRODUCT(PRODUCT(B7:B18+1)-1) -> -0.29880275 | AX7: =SUMPRODUCT(PRODUCT(C7:C18+1)-1) -> 0.13544174 | AY7: =SUMPRODUCT(PRODUCT(D7:D18+1)-1) -> -0.044511781 | AZ7: =SUMPRODUCT(PRODUCT(E7:E18+1)-1) -> 0.55634768 | BA7: =SUMPRODUCT(PRODUCT(F7:F18+1)-1) -> 0.60890247 | BB7: =SUMPRODUCT(PRODUCT(G7:G18+1)-1) -> 0.1466194 | BC7: =SUMPRODUCT(PRODUCT(H7:H18+1)-1) -> 0.20802979 | BD7: =SUMPRODUCT(PRODUCT(I7:I18+1)-1) -> 0.17863475 | BH7: 42767 | BI7: =STDEV(B7:B18)*SQRT(12) -> 0.18110199 | BJ7: =STDEV(C7:C18)*SQRT(12) -> 0.002808267 | BK7: =STDEV(D7:D18)*SQRT(12) -> 0.19810509 | BL7: =STDEV(E7:E18)*SQRT(12) -> 0.26573157 | BM7: =STDEV(F7:F18)*SQRT(12) -> 0.24547903 | BN7: =STDEV(G7:G18)*SQRT(12) -> 0.011428382 | BO7: =STDEV(H7:H18)*SQRT(12) -> 0.06036031 | BP7: =STDEV(I7:I18)*SQRT(12) -> 0.074554488
A8: 42461 | B8: -0.0503 | C8: 0.0105 | D8: -0.0404 | E8: 0.0722 | F8: 0.0542 | G8: =SUMPRODUCT($B8:$F8,Carteiras!$M$16:$Q$16) -> 0.01104 | H8: =SUMPRODUCT($B8:$F8,Carteiras!$M$17:$Q$17) -> 0.015635 | I8: =SUMPRODUCT($B8:$F8,Carteiras!$M$18:$Q$18) -> 0.005345 | L8: 2019 | M8: {=SUMPRODUCT(PRODUCT(B41:B52+1)-1)} -> 0.0107009 | N8: {=SUMPRODUCT(PRODUCT(C41:C52+1)-1)} -> 0.059459404 | O8: {=SUMPRODUCT(PRODUCT(D41:D52+1)-1)} -> 0.35055876 | P8: {=SUMPRODUCT(PRODUCT(E41:E52+1)-1)} -> 0.31466468 | Q8: {=SUMPRODUCT(PRODUCT(F41:F52+1)-1)} -> 0.56718649 | R8: =SUMPRODUCT(PRODUCT(G41:G52+1)-1) -> 0.085233921 | S8: =SUMPRODUCT(PRODUCT(H41:H52+1)-1) -> 0.20684351 | T8: =SUMPRODUCT(PRODUCT(I41:I52+1)-1) -> 0.29881904 | X8: Risco | Y8: =STDEV(B5:B1011)*SQRT(12) -> 0.16361412 | Z8: =STDEV(C5:C1011)*SQRT(12) -> 0.010928306 | AA8: =STDEV(D5:D1011)*SQRT(12) -> 0.18958047 | AB8: =STDEV(E5:E1011)*SQRT(12) -> 0.25261121 | AC8: =STDEV(F5:F1011)*SQRT(12) -> 0.27495051 | AD8: =STDEV(G5:G1011)*SQRT(12) -> 0.016421044 | AE8: =STDEV(H5:H1011)*SQRT(12) -> 0.074695573 | AF8: =STDEV(I5:I1011)*SQRT(12) -> 0.099252936 | AJ8: 42461 | AK8: =AK7*(1+B7) -> 88.82625 | AL8: =AL7*(1+C7) -> 103.08111 | AM8: =AM7*(1+D7) -> 90.865132 | AN8: =AN7*(1+E7) -> 115.45744 | AO8: =AO7*(1+F7) -> 106.54131 | AP8: =AP7*(1+G7) -> 103.11489 | AQ8: =AQ7*(1+H7) -> 103.04372 | AR8: =AR7*(1+I7) -> 99.773687 | AV8: 42795 | AW8: =SUMPRODUCT(PRODUCT(B8:B19+1)-1) -> -0.21580775 | AX8: =SUMPRODUCT(PRODUCT(C8:C19+1)-1) -> 0.13600384 | AY8: =SUMPRODUCT(PRODUCT(D8:D19+1)-1) -> 0.0047888407 | AZ8: =SUMPRODUCT(PRODUCT(E8:E19+1)-1) -> 0.29083357 | BA8: =SUMPRODUCT(PRODUCT(F8:F19+1)-1) -> 0.41845801 | BB8: =SUMPRODUCT(PRODUCT(G8:G19+1)-1) -> 0.13859508 | BC8: =SUMPRODUCT(PRODUCT(H8:H19+1)-1) -> 0.16490441 | BD8: =SUMPRODUCT(PRODUCT(I8:I19+1)-1) -> 0.15060516 | BH8: 42795 | BI8: =STDEV(B8:B19)*SQRT(12) -> 0.15726398 | BJ8: =STDEV(C8:C19)*SQRT(12) -> 0.0027269697 | BK8: =STDEV(D8:D19)*SQRT(12) -> 0.19161441 | BL8: =STDEV(E8:E19)*SQRT(12) -> 0.22902687 | BM8: =STDEV(F8:F19)*SQRT(12) -> 0.23784861 | BN8: =STDEV(G8:G19)*SQRT(12) -> 0.011065279 | BO8: =STDEV(H8:H19)*SQRT(12) -> 0.058562613 | BP8: =STDEV(I8:I19)*SQRT(12) -> 0.076233988
A9: 42492 | B9: 0.0437 | C9: 0.0105 | D9: 0.0695 | E9: -0.0984 | F9: -0.0512 | G9: =SUMPRODUCT($B9:$F9,Carteiras!$M$16:$Q$16) -> 0.008005 | H9: =SUMPRODUCT($B9:$F9,Carteiras!$M$17:$Q$17) -> -0.00458 | I9: =SUMPRODUCT($B9:$F9,Carteiras!$M$18:$Q$18) -> 0.007565 | L9: 2020 | M9: {=SUMPRODUCT(PRODUCT(B53:B64+1)-1)} -> 0.32743671 | N9: {=SUMPRODUCT(PRODUCT(C53:C64+1)-1)} -> 0.027538158 | O9: {=SUMPRODUCT(PRODUCT(D53:D64+1)-1)} -> 0.51425532 | P9: {=SUMPRODUCT(PRODUCT(E53:E64+1)-1)} -> 0.030806949 | Q9: {=SUMPRODUCT(PRODUCT(F53:F64+1)-1)} -> -0.0082873994 | R9: =SUMPRODUCT(PRODUCT(G53:G64+1)-1) -> 0.054025761 | S9: =SUMPRODUCT(PRODUCT(H53:H64+1)-1) -> 0.13181155 | T9: =SUMPRODUCT(PRODUCT(I53:I64+1)-1) -> 0.21852051 | X9: Sharpe | Y9: =(Y7-$Z$7)/Y8 -> -0.37216154 | Z9: =(Z7-$Z$7)/Z8 -> 0 | AA9: =(AA7-$Z$7)/AA8 -> 0.73792636 | AB9: =(AB7-$Z$7)/AB8 -> 0.56564232 | AC9: =(AC7-$Z$7)/AC8 -> 0.70511281 | AD9: =(AD7-$Z$7)/AD8 -> 0.97963432 | AE9: =(AE7-$Z$7)/AE8 -> 1.0563703 | AF9: =(AF7-$Z$7)/AF8 -> 1.1709497 | AJ9: 42492 | AK9: =AK8*(1+B8) -> 84.358289 | AL9: =AL8*(1+C8) -> 104.16346 | AM9: =AM8*(1+D8) -> 87.194181 | AN9: =AN8*(1+E8) -> 123.79347 | AO9: =AO8*(1+F8) -> 112.31584 | AP9: =AP8*(1+G8) -> 104.25328 | AQ9: =AQ8*(1+H8) -> 104.65481 | AR9: =AR8*(1+I8) -> 100.30698 | AV9: 42828 | AW9: =SUMPRODUCT(PRODUCT(B9:B20+1)-1) -> -0.16502559 | AX9: =SUMPRODUCT(PRODUCT(C9:C20+1)-1) -> 0.13308092 | AY9: =SUMPRODUCT(PRODUCT(D9:D20+1)-1) -> 0.079969998 | AZ9: =SUMPRODUCT(PRODUCT(E9:E20+1)-1) -> 0.2117366 | BA9: =SUMPRODUCT(PRODUCT(F9:F20+1)-1) -> 0.39114375 | BB9: =SUMPRODUCT(PRODUCT(G9:G20+1)-1) -> 0.13630334 | BC9: =SUMPRODUCT(PRODUCT(H9:H20+1)-1) -> 0.16449723 | BD9: =SUMPRODUCT(PRODUCT(I9:I20+1)-1) -> 0.17082253 | BH9: 42828 | BI9: =STDEV(B9:B20)*SQRT(12) -> 0.15596276 | BJ9: =STDEV(C9:C20)*SQRT(12) -> 0.0039033785 | BK9: =STDEV(D9:D20)*SQRT(12) -> 0.18777432 | BL9: =STDEV(E9:E20)*SQRT(12) -> 0.22312885 | BM9: =STDEV(F9:F20)*SQRT(12) -> 0.23661211 | BN9: =STDEV(G9:G20)*SQRT(12) -> 0.011219152 | BO9: =STDEV(H9:H20)*SQRT(12) -> 0.058545793 | BP9: =STDEV(I9:I20)*SQRT(12) -> 0.076603792
A10: 42522 | B10: -0.1204 | C10: 0.0116 | D10: -0.1109 | E10: 0.0613 | F10: 0.0947 | G10: =SUMPRODUCT($B10:$F10,Carteiras!$M$16:$Q$16) -> 0.00796 | H10: =SUMPRODUCT($B10:$F10,Carteiras!$M$17:$Q$17) -> 0.006545 | I10: =SUMPRODUCT($B10:$F10,Carteiras!$M$18:$Q$18) -> -0.010935 | L10: 2021 | M10: {=SUMPRODUCT(PRODUCT(B65:B76+1)-1)} -> -0.0023299891 | N10: =SUMPRODUCT(PRODUCT(C65:C76+1)-1) -> 0.0096363274 | O10: {=SUMPRODUCT(PRODUCT(D65:D76+1)-1)} -> 0.13309736 | P10: {=SUMPRODUCT(PRODUCT(E65:E76+1)-1)} -> 0.057464231 | Q10: {=SUMPRODUCT(PRODUCT(F65:F76+1)-1)} -> 0.1039727 | R10: =SUMPRODUCT(PRODUCT(G65:G76+1)-1) -> 0.018296189 | S10: =SUMPRODUCT(PRODUCT(H65:H76+1)-1) -> 0.049816691 | T10: =SUMPRODUCT(PRODUCT(I65:I76+1)-1) -> 0.077684087 | X10: Retorno Máximo | Y10: =MAX(B5:B1024) -> 0.1578 | Z10: =MAX(C5:C1024) -> 0.0116 | AA10: =MAX(D5:D1024) -> 0.179 | AB10: =MAX(E5:E1024) -> 0.1735 | AC10: =MAX(F5:F1024) -> 0.1753 | AD10: =MAX(G5:G1024) -> 0.018585 | AE10: =MAX(H5:H1024) -> 0.070205 | AF10: =MAX(I5:I1024) -> 0.109985 | AJ10: 42522 | AK10: =AK9*(1+B9) -> 88.044747 | AL10: =AL9*(1+C9) -> 105.25717 | AM10: =AM9*(1+D9) -> 93.254177 | AN10: =AN9*(1+E9) -> 111.61219 | AO10: =AO9*(1+F9) -> 106.56527 | AP10: =AP9*(1+G9) -> 105.08783 | AQ10: =AQ9*(1+H9) -> 104.17549 | AR10: =AR9*(1+I9) -> 101.0658 | AV10: 42857 | AW10: =SUMPRODUCT(PRODUCT(B10:B21+1)-1) -> -0.19366608 | AX10: =SUMPRODUCT(PRODUCT(C10:C21+1)-1) -> 0.13173535 | AY10: =SUMPRODUCT(PRODUCT(D10:D21+1)-1) -> 0.041295056 | AZ10: =SUMPRODUCT(PRODUCT(E10:E21+1)-1) -> 0.28807493 | BA10: =SUMPRODUCT(PRODUCT(F10:F21+1)-1) -> 0.45448419 | BB10: =SUMPRODUCT(PRODUCT(G10:G21+1)-1) -> 0.13612861 | BC10: =SUMPRODUCT(PRODUCT(H10:H21+1)-1) -> 0.17252829 | BD10: =SUMPRODUCT(PRODUCT(I10:I21+1)-1) -> 0.17132221 | BH10: 42857 | BI10: =STDEV(B10:B21)*SQRT(12) -> 0.14526883 | BJ10: =STDEV(C10:C21)*SQRT(12) -> 0.0040729708 | BK10: =STDEV(D10:D21)*SQRT(12) -> 0.17767812 | BL10: =STDEV(E10:E21)*SQRT(12) -> 0.19643461 | BM10: =STDEV(F10:F21)*SQRT(12) -> 0.224058 | BN10: =STDEV(G10:G21)*SQRT(12) -> 0.011260913 | BO10: =STDEV(H10:H21)*SQRT(12) -> 0.056682675 | BP10: =STDEV(I10:I21)*SQRT(12) -> 0.076568972
A11: 42552 | B11: 0.0031 | C11: 0.0116 | D11: 0.0471 | E11: 0.1158 | F11: 0.1455 | G11: =SUMPRODUCT($B11:$F11,Carteiras!$M$16:$Q$16) -> 0.018585 | H11: =SUMPRODUCT($B11:$F11,Carteiras!$M$17:$Q$17) -> 0.052215 | I11: =SUMPRODUCT($B11:$F11,Carteiras!$M$18:$Q$18) -> 0.06678 | X11: Retorno Mínimo | Y11: =MIN(B5:B1024) -> -0.1204 | Z11: =MIN(C5:C1024) -> 0.0013 | AA11: =MIN(D5:D1024) -> -0.1382 | AB11: =MIN(E5:E1024) -> -0.3106 | AC11: =MIN(F5:F1024) -> -0.3748 | AD11: =MIN(G5:G1024) -> -0.01139 | AE11: =MIN(H5:H1024) -> -0.08998 | AF11: =MIN(I5:I1024) -> -0.10486 | AJ11: 42552 | AK11: =AK10*(1+B10) -> 77.444159 | AL11: =AL10*(1+C10) -> 106.47816 | AM11: =AM10*(1+D10) -> 82.912288 | AN11: =AN10*(1+E10) -> 118.45402 | AO11: =AO10*(1+F10) -> 116.657 | AP11: =AP10*(1+G10) -> 105.92433 | AQ11: =AQ10*(1+H10) -> 104.85732 | AR11: =AR10*(1+I10) -> 99.960645 | AV11: 42887 | AW11: =SUMPRODUCT(PRODUCT(B11:B22+1)-1) -> -0.067069088 | AX11: =SUMPRODUCT(PRODUCT(C11:C22+1)-1) -> 0.1278197 | AY11: =SUMPRODUCT(PRODUCT(D11:D22+1)-1) -> 0.20771956 | AZ11: =SUMPRODUCT(PRODUCT(E11:E22+1)-1) -> 0.22107999 | BA11: =SUMPRODUCT(PRODUCT(F11:F22+1)-1) -> 0.32972301 | BB11: =SUMPRODUCT(PRODUCT(G11:G22+1)-1) -> 0.13747556 | BC11: =SUMPRODUCT(PRODUCT(H11:H22+1)-1) -> 0.17731022 | BD11: =SUMPRODUCT(PRODUCT(I11:I22+1)-1) -> 0.20049675 | BH11: 42887 | BI11: =STDEV(B11:B22)*SQRT(12) -> 0.094864089 | BJ11: =STDEV(C11:C22)*SQRT(12) -> 0.0044069161 | BK11: =STDEV(D11:D22)*SQRT(12) -> 0.12630409 | BL11: =STDEV(E11:E22)*SQRT(12) -> 0.19232725 | BM11: =STDEV(F11:F22)*SQRT(12) -> 0.21562221 | BN11: =STDEV(G11:G22)*SQRT(12) -> 0.011004539 | BO11: =STDEV(H11:H22)*SQRT(12) -> 0.05628267 | BP11: =STDEV(I11:I22)*SQRT(12) -> 0.071813995
A12: 42583 | B12: -0.0184 | C12: 0.0111 | D12: -0.0027 | E12: 0.0045 | F12: 0 | G12: =SUMPRODUCT($B12:$F12,Carteiras!$M$16:$Q$16) -> 0.01008 | H12: =SUMPRODUCT($B12:$F12,Carteiras!$M$17:$Q$17) -> 0.0049 | I12: =SUMPRODUCT($B12:$F12,Carteiras!$M$18:$Q$18) -> 0.00035 | AJ12: 42583 | AK12: =AK11*(1+B11) -> 77.684236 | AL12: =AL11*(1+C11) -> 107.7133 | AM12: =AM11*(1+D11) -> 86.817457 | AN12: =AN11*(1+E11) -> 132.171 | AO12: =AO11*(1+F11) -> 133.6306 | AP12: =AP11*(1+G11) -> 107.89293 | AQ12: =AQ11*(1+H11) -> 110.33245 | AR12: =AR11*(1+I11) -> 106.63602 | AV12: 42919 | AW12: =SUMPRODUCT(PRODUCT(B12:B23+1)-1) -> -0.12538308 | AX12: =SUMPRODUCT(PRODUCT(C12:C23+1)-1) -> 0.1238061 | AY12: =SUMPRODUCT(PRODUCT(D12:D23+1)-1) -> 0.10737422 | AZ12: =SUMPRODUCT(PRODUCT(E12:E23+1)-1) -> 0.14447522 | BA12: =SUMPRODUCT(PRODUCT(F12:F23+1)-1) -> 0.25670723 | BB12: =SUMPRODUCT(PRODUCT(G12:G23+1)-1) -> 0.12509112 | BC12: =SUMPRODUCT(PRODUCT(H12:H23+1)-1) -> 0.13488201 | BD12: =SUMPRODUCT(PRODUCT(I12:I23+1)-1) -> 0.1378825 | BH12: 42919 | BI12: =STDEV(B12:B23)*SQRT(12) -> 0.1084632 | BJ12: =STDEV(C12:C23)*SQRT(12) -> 0.0045169378 | BK12: =STDEV(D12:D23)*SQRT(12) -> 0.13304967 | BL12: =STDEV(E12:E23)*SQRT(12) -> 0.1642397 | BM12: =STDEV(F12:F23)*SQRT(12) -> 0.18442615 | BN12: =STDEV(G12:G23)*SQRT(12) -> 0.0074591305 | BO12: =STDEV(H12:H23)*SQRT(12) -> 0.037796235 | BP12: =STDEV(I12:I23)*SQRT(12) -> 0.045079972
A13: 42614 | B13: 0.0015 | C13: 0.0111 | D13: 0.0017 | E13: 0.0113 | F13: 0.0014 | G13: =SUMPRODUCT($B13:$F13,Carteiras!$M$16:$Q$16) -> 0.01064 | H13: =SUMPRODUCT($B13:$F13,Carteiras!$M$17:$Q$17) -> 0.007785 | I13: =SUMPRODUCT($B13:$F13,Carteiras!$M$18:$Q$18) -> 0.00442 | AJ13: 42614 | AK13: =AK12*(1+B12) -> 76.254846 | AL13: =AL12*(1+C12) -> 108.90892 | AM13: =AM12*(1+D12) -> 86.58305 | AN13: =AN12*(1+E12) -> 132.76576 | AO13: =AO12*(1+F12) -> 133.6306 | AP13: =AP12*(1+G12) -> 108.98049 | AQ13: =AQ12*(1+H12) -> 110.87307 | AR13: =AR12*(1+I12) -> 106.67334 | AV13: 42948 | AW13: =SUMPRODUCT(PRODUCT(B13:B24+1)-1) -> -0.10898847 | AX13: =SUMPRODUCT(PRODUCT(C13:C24+1)-1) -> 0.12036055 | AY13: =SUMPRODUCT(PRODUCT(D13:D24+1)-1) -> 0.12136491 | AZ13: =SUMPRODUCT(PRODUCT(E13:E24+1)-1) -> 0.22320418 | BA13: =SUMPRODUCT(PRODUCT(F13:F24+1)-1) -> 0.36566374 | BB13: =SUMPRODUCT(PRODUCT(G13:G24+1)-1) -> 0.12653358 | BC13: =SUMPRODUCT(PRODUCT(H13:H24+1)-1) -> 0.16269785 | BD13: =SUMPRODUCT(PRODUCT(I13:I24+1)-1) -> 0.17690958 | BH13: 42948 | BI13: =STDEV(B13:B24)*SQRT(12) -> 0.10858959 | BJ13: =STDEV(C13:C24)*SQRT(12) -> 0.004588127 | BK13: =STDEV(D13:D24)*SQRT(12) -> 0.13241624 | BL13: =STDEV(E13:E24)*SQRT(12) -> 0.1748493 | BM13: =STDEV(F13:F24)*SQRT(12) -> 0.1940454 | BN13: =STDEV(G13:G24)*SQRT(12) -> 0.007609332 | BO13: =STDEV(H13:H24)*SQRT(12) -> 0.041545111 | BP13: =STDEV(I13:I24)*SQRT(12) -> 0.04919033
A14: 42644 | B14: -0.0299 | C14: 0.0111 | D14: -0.0326 | E14: 0.1121 | F14: 0.0705 | G14: =SUMPRODUCT($B14:$F14,Carteiras!$M$16:$Q$16) -> 0.013965 | H14: =SUMPRODUCT($B14:$F14,Carteiras!$M$17:$Q$17) -> 0.026555 | I14: =SUMPRODUCT($B14:$F14,Carteiras!$M$18:$Q$18) -> 0.01676 | AJ14: 42644 | AK14: =AK13*(1+B13) -> 76.369228 | AL14: =AL13*(1+C13) -> 110.11781 | AM14: =AM13*(1+D13) -> 86.730241 | AN14: =AN13*(1+E13) -> 134.26602 | AO14: =AO13*(1+F13) -> 133.81768 | AP14: =AP13*(1+G13) -> 110.14004 | AQ14: =AQ13*(1+H13) -> 111.73622 | AR14: =AR13*(1+I13) -> 107.14484 | AV14: 42979 | AW14: =SUMPRODUCT(PRODUCT(B14:B25+1)-1) -> -0.10970021 | AX14: =SUMPRODUCT(PRODUCT(C14:C25+1)-1) -> 0.11515266 | AY14: =SUMPRODUCT(PRODUCT(D14:D25+1)-1) -> 0.14834394 | AZ14: =SUMPRODUCT(PRODUCT(E14:E25+1)-1) -> 0.26553795 | BA14: =SUMPRODUCT(PRODUCT(F14:F25+1)-1) -> 0.41053126 | BB14: =SUMPRODUCT(PRODUCT(G14:G25+1)-1) -> 0.12511237 | BC14: =SUMPRODUCT(PRODUCT(H14:H25+1)-1) -> 0.17586175 | BD14: =SUMPRODUCT(PRODUCT(I14:I25+1)-1) -> 0.19752618 | BH14: 42979 | BI14: =STDEV(B14:B25)*SQRT(12) -> 0.10850718 | BJ14: =STDEV(C14:C25)*SQRT(12) -> 0.0051869592 | BK14: =STDEV(D14:D25)*SQRT(12) -> 0.13291251 | BL14: =STDEV(E14:E25)*SQRT(12) -> 0.17686308 | BM14: =STDEV(F14:F25)*SQRT(12) -> 0.19195565 | BN14: =STDEV(G14:G25)*SQRT(12) -> 0.0075955723 | BO14: =STDEV(H14:H25)*SQRT(12) -> 0.041637388 | BP14: =STDEV(I14:I25)*SQRT(12) -> 0.048690682
A15: 42675 | B15: 0.0521 | C15: 0.0104 | D15: 0.1004 | E15: -0.0461 | F15: -0.0756 | G15: =SUMPRODUCT($B15:$F15,Carteiras!$M$16:$Q$16) -> 0.012075 | H15: =SUMPRODUCT($B15:$F15,Carteiras!$M$17:$Q$17) -> 0.00461 | I15: =SUMPRODUCT($B15:$F15,Carteiras!$M$18:$Q$18) -> 0.012945 | AJ15: 42675 | AK15: =AK14*(1+B14) -> 74.085788 | AL15: =AL14*(1+C14) -> 111.34012 | AM15: =AM14*(1+D14) -> 83.902835 | AN15: =AN14*(1+E14) -> 149.31724 | AO15: =AO14*(1+F14) -> 143.25183 | AP15: =AP14*(1+G14) -> 111.67815 | AQ15: =AQ14*(1+H14) -> 114.70338 | AR15: =AR14*(1+I14) -> 108.94058 | AV15: 43010 | AW15: =SUMPRODUCT(PRODUCT(B15:B26+1)-1) -> -0.054819347 | AX15: =SUMPRODUCT(PRODUCT(C15:C26+1)-1) -> 0.10996898 | AY15: =SUMPRODUCT(PRODUCT(D15:D26+1)-1) -> 0.25256619 | AZ15: =SUMPRODUCT(PRODUCT(E15:E26+1)-1) -> 0.14104389 | BA15: =SUMPRODUCT(PRODUCT(F15:F26+1)-1) -> 0.30077204 | BB15: =SUMPRODUCT(PRODUCT(G15:G26+1)-1) -> 0.1192203 | BC15: =SUMPRODUCT(PRODUCT(H15:H26+1)-1) -> 0.15857127 | BD15: =SUMPRODUCT(PRODUCT(I15:I26+1)-1) -> 0.19833297 | BH15: 43010 | BI15: =STDEV(B15:B26)*SQRT(12) -> 0.11245838 | BJ15: =STDEV(C15:C26)*SQRT(12) -> 0.0053611396 | BK15: =STDEV(D15:D26)*SQRT(12) -> 0.12954901 | BL15: =STDEV(E15:E26)*SQRT(12) -> 0.14662943 | BM15: =STDEV(F15:F26)*SQRT(12) -> 0.1910719 | BN15: =STDEV(G15:G26)*SQRT(12) -> 0.0062044061 | BO15: =STDEV(H15:H26)*SQRT(12) -> 0.039201327 | BP15: =STDEV(I15:I26)*SQRT(12) -> 0.048719056
A16: 42705 | B16: -0.0465 | C16: 0.0104 | D16: -0.0181 | E16: -0.0293 | F16: -0.0164 | G16: =SUMPRODUCT($B16:$F16,Carteiras!$M$16:$Q$16) -> 0.00699 | H16: =SUMPRODUCT($B16:$F16,Carteiras!$M$17:$Q$17) -> -0.006695 | I16: =SUMPRODUCT($B16:$F16,Carteiras!$M$18:$Q$18) -> -0.013865 | AJ16: 42705 | AK16: =AK15*(1+B15) -> 77.945658 | AL16: =AL15*(1+C15) -> 112.49805 | AM16: =AM15*(1+D15) -> 92.32668 | AN16: =AN15*(1+E15) -> 142.43371 | AO16: =AO15*(1+F15) -> 132.42199 | AP16: =AP15*(1+G15) -> 113.02666 | AQ16: =AQ15*(1+H15) -> 115.23216 | AR16: =AR15*(1+I15) -> 110.35082 | AV16: 43040 | AW16: =SUMPRODUCT(PRODUCT(B16:B27+1)-1) -> -0.10315194 | AX16: =SUMPRODUCT(PRODUCT(C16:C27+1)-1) -> 0.10480583 | AY16: =SUMPRODUCT(PRODUCT(D16:D27+1)-1) -> 0.16981304 | AZ16: =SUMPRODUCT(PRODUCT(E16:E27+1)-1) -> 0.15671395 | BA16: =SUMPRODUCT(PRODUCT(F16:F27+1)-1) -> 0.36775251 | BB16: =SUMPRODUCT(PRODUCT(G16:G27+1)-1) -> 0.111247 | BC16: =SUMPRODUCT(PRODUCT(H16:H27+1)-1) -> 0.15068301 | BD16: =SUMPRODUCT(PRODUCT(I16:I27+1)-1) -> 0.18244502 | BH16: 43040 | BI16: =STDEV(B16:B27)*SQRT(12) -> 0.094513126 | BJ16: =STDEV(C16:C27)*SQRT(12) -> 0.0058086925 | BK16: =STDEV(D16:D27)*SQRT(12) -> 0.096159238 | BL16: =STDEV(E16:E27)*SQRT(12) -> 0.1414744 | BM16: =STDEV(F16:F27)*SQRT(12) -> 0.1687617 | BN16: =STDEV(G16:G27)*SQRT(12) -> 0.0069926188 | BO16: =STDEV(H16:H27)*SQRT(12) -> 0.041228295 | BP16: =STDEV(I16:I27)*SQRT(12) -> 0.051209178
A17: 42737 | B17: -0.0406 | C17: 0.0108 | D17: -0.0211 | E17: 0.0713 | F17: 0.1183 | G17: =SUMPRODUCT($B17:$F17,Carteiras!$M$16:$Q$16) -> 0.01223 | H17: =SUMPRODUCT($B17:$F17,Carteiras!$M$17:$Q$17) -> 0.028645 | I17: =SUMPRODUCT($B17:$F17,Carteiras!$M$18:$Q$18) -> 0.031365 | AJ17: 42737 | AK17: =AK16*(1+B16) -> 74.321185 | AL17: =AL16*(1+C16) -> 113.66803 | AM17: =AM16*(1+D16) -> 90.655567 | AN17: =AN16*(1+E16) -> 138.26041 | AO17: =AO16*(1+F16) -> 130.25027 | AP17: =AP16*(1+G16) -> 113.81672 | AQ17: =AQ16*(1+H16) -> 114.46068 | AR17: =AR16*(1+I16) -> 108.8208 | AV17: 43070 | AW17: =SUMPRODUCT(PRODUCT(B17:B28+1)-1) -> -0.050479163 | AX17: =SUMPRODUCT(PRODUCT(C17:C28+1)-1) -> 0.099666687 | AY17: =SUMPRODUCT(PRODUCT(D17:D28+1)-1) -> 0.23152637 | AZ17: =SUMPRODUCT(PRODUCT(E17:E28+1)-1) -> 0.26753542 | BA17: =SUMPRODUCT(PRODUCT(F17:F28+1)-1) -> 0.49624004 | BB17: =SUMPRODUCT(PRODUCT(G17:G28+1)-1) -> 0.11456864 | BC17: =SUMPRODUCT(PRODUCT(H17:H28+1)-1) -> 0.19242156 | BD17: =SUMPRODUCT(PRODUCT(I17:I28+1)-1) -> 0.24519836 | BH17: 43070 | BI17: =STDEV(B17:B28)*SQRT(12) -> 0.086303081 | BJ17: =STDEV(C17:C28)*SQRT(12) -> 0.0058926765 | BK17: =STDEV(D17:D28)*SQRT(12) -> 0.091419488 | BL17: =STDEV(E17:E28)*SQRT(12) -> 0.1417371 | BM17: =STDEV(F17:F28)*SQRT(12) -> 0.16784336 | BN17: =STDEV(G17:G28)*SQRT(12) -> 0.0067725596 | BO17: =STDEV(H17:H28)*SQRT(12) -> 0.039264891 | BP17: =STDEV(I17:I28)*SQRT(12) -> 0.04648655
A18: 42767 | B18: -0.0172 | C18: 0.0086 | D18: 0.0281 | E18: 0.0338 | F18: 0.0545 | G18: =SUMPRODUCT($B18:$F18,Carteiras!$M$16:$Q$16) -> 0.010835 | H18: =SUMPRODUCT($B18:$F18,Carteiras!$M$17:$Q$17) -> 0.0209 | I18: =SUMPRODUCT($B18:$F18,Carteiras!$M$18:$Q$18) -> 0.0269 | AJ18: 42767 | AK18: =AK17*(1+B17) -> 71.303745 | AL18: =AL17*(1+C17) -> 114.89565 | AM18: =AM17*(1+D17) -> 88.742735 | AN18: =AN17*(1+E17) -> 148.11837 | AO18: =AO17*(1+F17) -> 145.65888 | AP18: =AP17*(1+G17) -> 115.2087 | AQ18: =AQ17*(1+H17) -> 117.73941 | AR18: =AR17*(1+I17) -> 112.23397 | AV18: 43102 | AW18: =SUMPRODUCT(PRODUCT(B18:B29+1)-1) -> -0.05295342 | AX18: =SUMPRODUCT(PRODUCT(C18:C29+1)-1) -> 0.094227101 | AY18: =SUMPRODUCT(PRODUCT(D18:D29+1)-1) -> 0.26813625 | AZ18: =SUMPRODUCT(PRODUCT(E18:E29+1)-1) -> 0.31427083 | BA18: =SUMPRODUCT(PRODUCT(F18:F29+1)-1) -> 0.39161161 | BB18: =SUMPRODUCT(PRODUCT(G18:G29+1)-1) -> 0.11339046 | BC18: =SUMPRODUCT(PRODUCT(H18:H29+1)-1) -> 0.18770934 | BD18: =SUMPRODUCT(PRODUCT(I18:I29+1)-1) -> 0.22798786 | BH18: 43102 | BI18: =STDEV(B18:B29)*SQRT(12) -> 0.087487241 | BJ18: =STDEV(C18:C29)*SQRT(12) -> 0.0053509557 | BK18: =STDEV(D18:D29)*SQRT(12) -> 0.082054549 | BL18: =STDEV(E18:E29)*SQRT(12) -> 0.16127535 | BM18: =STDEV(F18:F29)*SQRT(12) -> 0.14179358 | BN18: =STDEV(G18:G29)*SQRT(12) -> 0.00629782 | BO18: =STDEV(H18:H29)*SQRT(12) -> 0.037891215 | BP18: =STDEV(I18:I29)*SQRT(12) -> 0.044326269
A19: 42795 | B19: -0.006 | C19: 0.0105 | D19: 0.0007 | E19: -0.0267 | F19: -0.0161 | G19: =SUMPRODUCT($B19:$F19,Carteiras!$M$16:$Q$16) -> 0.00815 | H19: =SUMPRODUCT($B19:$F19,Carteiras!$M$17:$Q$17) -> -0.001365 | I19: =SUMPRODUCT($B19:$F19,Carteiras!$M$18:$Q$18) -> -0.00393 | AJ19: 42795 | AK19: =AK18*(1+B18) -> 70.07732 | AL19: =AL18*(1+C18) -> 115.88375 | AM19: =AM18*(1+D18) -> 91.236405 | AN19: =AN18*(1+E18) -> 153.12477 | AO19: =AO18*(1+F18) -> 153.59729 | AP19: =AP18*(1+G18) -> 116.45698 | AQ19: =AQ18*(1+H18) -> 120.20016 | AR19: =AR18*(1+I18) -> 115.25306 | AV19: 43132 | AW19: =SUMPRODUCT(PRODUCT(B19:B30+1)-1) -> -0.020575759 | AX19: =SUMPRODUCT(PRODUCT(C19:C30+1)-1) -> 0.089887513 | AY19: =SUMPRODUCT(PRODUCT(D19:D30+1)-1) -> 0.21127303 | AZ19: =SUMPRODUCT(PRODUCT(E19:E30+1)-1) -> 0.2790558 | BA19: =SUMPRODUCT(PRODUCT(F19:F30+1)-1) -> 0.3111106 | BB19: =SUMPRODUCT(PRODUCT(G19:G30+1)-1) -> 0.10536084 | BC19: =SUMPRODUCT(PRODUCT(H19:H30+1)-1) -> 0.16381322 | BD19: =SUMPRODUCT(PRODUCT(I19:I30+1)-1) -> 0.19073208 | BH19: 43132 | BI19: =STDEV(B19:B30)*SQRT(12) -> 0.088497411 | BJ19: =STDEV(C19:C30)*SQRT(12) -> 0.0059433691 | BK19: =STDEV(D19:D30)*SQRT(12) -> 0.089825341 | BL19: =STDEV(E19:E30)*SQRT(12) -> 0.16181703 | BM19: =STDEV(F19:F30)*SQRT(12) -> 0.14278738 | BN19: =STDEV(G19:G30)*SQRT(12) -> 0.0079687412 | BO19: =STDEV(H19:H30)*SQRT(12) -> 0.039629601 | BP19: =STDEV(I19:I30)*SQRT(12) -> 0.047805149
A20: 42828 | B20: 0.0112 | C20: 0.0079 | D20: 0.0314 | E20: 0.0065 | F20: 0.0339 | G20: =SUMPRODUCT($B20:$F20,Carteiras!$M$16:$Q$16) -> 0.009005 | H20: =SUMPRODUCT($B20:$F20,Carteiras!$M$17:$Q$17) -> 0.01528 | I20: =SUMPRODUCT($B20:$F20,Carteiras!$M$18:$Q$18) -> 0.02301 | AJ20: 42828 | AK20: =AK19*(1+B19) -> 69.656857 | AL20: =AL19*(1+C19) -> 117.10053 | AM20: =AM19*(1+D19) -> 91.300271 | AN20: =AN19*(1+E19) -> 149.03634 | AO20: =AO19*(1+F19) -> 151.12437 | AP20: =AP19*(1+G19) -> 117.40611 | AQ20: =AQ19*(1+H19) -> 120.03609 | AR20: =AR19*(1+I19) -> 114.80012 | AV20: 43160 | AW20: =SUMPRODUCT(PRODUCT(B20:B31+1)-1) -> -0.00077050003 | AX20: =SUMPRODUCT(PRODUCT(C20:C31+1)-1) -> 0.084278987 | AY20: =SUMPRODUCT(PRODUCT(D20:D31+1)-1) -> 0.19807939 | AZ20: =SUMPRODUCT(PRODUCT(E20:E31+1)-1) -> 0.31309211 | BA20: =SUMPRODUCT(PRODUCT(F20:F31+1)-1) -> 0.33416398 | BB20: =SUMPRODUCT(PRODUCT(G20:G31+1)-1) -> 0.10105189 | BC20: =SUMPRODUCT(PRODUCT(H20:H31+1)-1) -> 0.16760079 | BD20: =SUMPRODUCT(PRODUCT(I20:I31+1)-1) -> 0.19542415 | BH20: 43160 | BI20: =STDEV(B20:B31)*SQRT(12) -> 0.089639095 | BJ20: =STDEV(C20:C31)*SQRT(12) -> 0.0049923578 | BK20: =STDEV(D20:D31)*SQRT(12) -> 0.092525535 | BL20: =STDEV(E20:E31)*SQRT(12) -> 0.15530935 | BM20: =STDEV(F20:F31)*SQRT(12) -> 0.13852675 | BN20: =STDEV(G20:G31)*SQRT(12) -> 0.0089978194 | BO20: =STDEV(H20:H31)*SQRT(12) -> 0.038480618 | BP20: =STDEV(I20:I31)*SQRT(12) -> 0.046269411
A21: 42857 | B21: 0.0079 | C21: 0.0093 | D21: 0.0312 | E21: -0.0416 | F21: -0.008 | G21: =SUMPRODUCT($B21:$F21,Carteiras!$M$16:$Q$16) -> 0.00785 | H21: =SUMPRODUCT($B21:$F21,Carteiras!$M$17:$Q$17) -> 0.002285 | I21: =SUMPRODUCT($B21:$F21,Carteiras!$M$18:$Q$18) -> 0.007995 | AJ21: 42857 | AK21: =AK20*(1+B20) -> 70.437013 | AL21: =AL20*(1+C20) -> 118.02562 | AM21: =AM20*(1+D20) -> 94.167099 | AN21: =AN20*(1+E20) -> 150.00508 | AO21: =AO20*(1+F20) -> 156.24749 | AP21: =AP20*(1+G20) -> 118.46335 | AQ21: =AQ20*(1+H20) -> 121.87024 | AR21: =AR20*(1+I20) -> 117.44167 | AV21: 43192 | AW21: =SUMPRODUCT(PRODUCT(B21:B32+1)-1) -> 0.046266015 | AX21: =SUMPRODUCT(PRODUCT(C21:C32+1)-1) -> 0.081374381 | AY21: =SUMPRODUCT(PRODUCT(D21:D32+1)-1) -> 0.236877 | AZ21: =SUMPRODUCT(PRODUCT(E21:E32+1)-1) -> 0.3164841 | BA21: =SUMPRODUCT(PRODUCT(F21:F32+1)-1) -> 0.31842087 | BB21: =SUMPRODUCT(PRODUCT(G21:G32+1)-1) -> 0.10036442 | BC21: =SUMPRODUCT(PRODUCT(H21:H32+1)-1) -> 0.17289092 | BD21: =SUMPRODUCT(PRODUCT(I21:I32+1)-1) -> 0.20778142 | BH21: 43192 | BI21: =STDEV(B21:B32)*SQRT(12) -> 0.10694921 | BJ21: =STDEV(C21:C32)*SQRT(12) -> 0.0050534417 | BK21: =STDEV(D21:D32)*SQRT(12) -> 0.10409232 | BL21: =STDEV(E21:E32)*SQRT(12) -> 0.15501397 | BM21: =STDEV(F21:F32)*SQRT(12) -> 0.13821094 | BN21: =STDEV(G21:G32)*SQRT(12) -> 0.0089473612 | BO21: =STDEV(H21:H32)*SQRT(12) -> 0.039042005 | BP21: =STDEV(I21:I32)*SQRT(12) -> 0.04935548
A22: 42887 | B22: 0.0177 | C22: 0.0081 | D22: 0.0312 | E22: 0.0061 | F22: 0.0008 | G22: =SUMPRODUCT($B22:$F22,Carteiras!$M$16:$Q$16) -> 0.009155 | H22: =SUMPRODUCT($B22:$F22,Carteiras!$M$17:$Q$17) -> 0.01065 | I22: =SUMPRODUCT($B22:$F22,Carteiras!$M$18:$Q$18) -> 0.0137 | AJ22: 42887 | AK22: =AK21*(1+B21) -> 70.993466 | AL22: =AL21*(1+C21) -> 119.12326 | AM22: =AM21*(1+D21) -> 97.105113 | AN22: =AN21*(1+E21) -> 143.76487 | AO22: =AO21*(1+F21) -> 154.99751 | AP22: =AP21*(1+G21) -> 119.39329 | AQ22: =AQ21*(1+H21) -> 122.14871 | AR22: =AR21*(1+I21) -> 118.38062 | AV22: 43222 | AW22: =SUMPRODUCT(PRODUCT(B22:B33+1)-1) -> 0.096819795 | AX22: =SUMPRODUCT(PRODUCT(C22:C33+1)-1) -> 0.076981598 | AY22: =SUMPRODUCT(PRODUCT(D22:D33+1)-1) -> 0.31951938 | AZ22: =SUMPRODUCT(PRODUCT(E22:E33+1)-1) -> 0.22321483 | BA22: =SUMPRODUCT(PRODUCT(F22:F33+1)-1) -> 0.18046514 | BB22: =SUMPRODUCT(PRODUCT(G22:G33+1)-1) -> 0.096390292 | BC22: =SUMPRODUCT(PRODUCT(H22:H33+1)-1) -> 0.1552967 | BD22: =SUMPRODUCT(PRODUCT(I22:I33+1)-1) -> 0.19577543 | BH22: 43222 | BI22: =STDEV(B22:B33)*SQRT(12) -> 0.11916877 | BJ22: =STDEV(C22:C33)*SQRT(12) -> 0.0042038943 | BK22: =STDEV(D22:D33)*SQRT(12) -> 0.13237881 | BL22: =STDEV(E22:E33)*SQRT(12) -> 0.19587741 | BM22: =STDEV(F22:F33)*SQRT(12) -> 0.19268035 | BN22: =STDEV(G22:G33)*SQRT(12) -> 0.009722955 | BO22: =STDEV(H22:H33)*SQRT(12) -> 0.046001126 | BP22: =STDEV(I22:I33)*SQRT(12) -> 0.05205986
A23: 42919 | B23: -0.0596 | C23: 0.008 | D23: -0.0399 | E23: 0.0458 | F23: 0.0826 | G23: =SUMPRODUCT($B23:$F23,Carteiras!$M$16:$Q$16) -> 0.007495 | H23: =SUMPRODUCT($B23:$F23,Carteiras!$M$17:$Q$17) -> 0.014295 | I23: =SUMPRODUCT($B23:$F23,Carteiras!$M$18:$Q$18) -> 0.01114 | AJ23: 42919 | AK23: =AK22*(1+B22) -> 72.25005 | AL23: =AL22*(1+C22) -> 120.08816 | AM23: =AM22*(1+D22) -> 100.13479 | AN23: =AN22*(1+E22) -> 144.64183 | AO23: =AO22*(1+F22) -> 155.1215 | AP23: =AP22*(1+G22) -> 120.48633 | AQ23: =AQ22*(1+H22) -> 123.4496 | AR23: =AR22*(1+I22) -> 120.00243 | AV23: 43252 | AW23: =SUMPRODUCT(PRODUCT(B23:B34+1)-1) -> 0.11912909 | AX23: =SUMPRODUCT(PRODUCT(C23:C34+1)-1) -> 0.073883447 | AY23: =SUMPRODUCT(PRODUCT(D23:D34+1)-1) -> 0.32284633 | AZ23: =SUMPRODUCT(PRODUCT(E23:E34+1)-1) -> 0.15476538 | BA23: =SUMPRODUCT(PRODUCT(F23:F34+1)-1) -> 0.13611513 | BB23: =SUMPRODUCT(PRODUCT(G23:G34+1)-1) -> 0.090637572 | BC23: =SUMPRODUCT(PRODUCT(H23:H34+1)-1) -> 0.13916725 | BD23: =SUMPRODUCT(PRODUCT(I23:I34+1)-1) -> 0.18165545 | BH23: 43252 | BI23: =STDEV(B23:B34)*SQRT(12) -> 0.12270026 | BJ23: =STDEV(C23:C34)*SQRT(12) -> 0.0037497879 | BK23: =STDEV(D23:D34)*SQRT(12) -> 0.13255795 | BL23: =STDEV(E23:E34)*SQRT(12) -> 0.20748388 | BM23: =STDEV(F23:F34)*SQRT(12) -> 0.19933337 | BN23: =STDEV(G23:G34)*SQRT(12) -> 0.010285082 | BO23: =STDEV(H23:H34)*SQRT(12) -> 0.048604263 | BP23: =STDEV(I23:I34)*SQRT(12) -> 0.053762535
A24: 42948 | B24: 0 | C24: 0.008 | D24: 0.0099 | E24: 0.0736 | F24: 0.0867 | G24: =SUMPRODUCT($B24:$F24,Carteiras!$M$16:$Q$16) -> 0.011375 | H24: =SUMPRODUCT($B24:$F24,Carteiras!$M$17:$Q$17) -> 0.02953 | I24: =SUMPRODUCT($B24:$F24,Carteiras!$M$18:$Q$18) -> 0.03466 | AJ24: 42948 | AK24: =AK23*(1+B23) -> 67.943947 | AL24: =AL23*(1+C23) -> 121.04887 | AM24: =AM23*(1+D23) -> 96.139414 | AN24: =AN23*(1+E23) -> 151.26643 | AO24: =AO23*(1+F23) -> 167.93454 | AP24: =AP23*(1+G23) -> 121.38938 | AQ24: =AQ23*(1+H23) -> 125.21431 | AR24: =AR23*(1+I23) -> 121.33926 | AV24: 43283 | AW24: =SUMPRODUCT(PRODUCT(B24:B35+1)-1) -> 0.14852348 | AX24: =SUMPRODUCT(PRODUCT(C24:C35+1)-1) -> 0.071113509 | AY24: =SUMPRODUCT(PRODUCT(D24:D35+1)-1) -> 0.38498607 | AZ24: =SUMPRODUCT(PRODUCT(E24:E35+1)-1) -> 0.19992689 | BA24: =SUMPRODUCT(PRODUCT(F24:F35+1)-1) -> 0.10389756 | BB24: =SUMPRODUCT(PRODUCT(G24:G35+1)-1) -> 0.092759319 | BC24: =SUMPRODUCT(PRODUCT(H24:H35+1)-1) -> 0.14841046 | BD24: =SUMPRODUCT(PRODUCT(I24:I35+1)-1) -> 0.19122074 | BH24: 43283 | BI24: =STDEV(B24:B35)*SQRT(12) -> 0.10915418 | BJ24: =STDEV(C24:C35)*SQRT(12) -> 0.0030395873 | BK24: =STDEV(D24:D35)*SQRT(12) -> 0.11529996 | BL24: =STDEV(E24:E35)*SQRT(12) -> 0.21814071 | BM24: =STDEV(F24:F35)*SQRT(12) -> 0.18963764 | BN24: =STDEV(G24:G35)*SQRT(12) -> 0.010517969 | BO24: =STDEV(H24:H35)*SQRT(12) -> 0.04989142 | BP24: =STDEV(I24:I35)*SQRT(12) -> 0.053891269
A25: 42979 | B25: 0.0007 | C25: 0.0064 | D25: 0.0258 | E25: 0.0463 | F25: 0.0343 | G25: =SUMPRODUCT($B25:$F25,Carteiras!$M$16:$Q$16) -> 0.009365 | H25: =SUMPRODUCT($B25:$F25,Carteiras!$M$17:$Q$17) -> 0.019195 | I25: =SUMPRODUCT($B25:$F25,Carteiras!$M$18:$Q$18) -> 0.022015 | Y25: DÓLAR | Z25: CDI | AA25: IVVB11 | AB25: BOVA11 | AC25: SMAL11 | AD25: Conservadora | AE25: Moderada | AF25: Agressiva | AJ25: 42979 | AK25: =AK24*(1+B24) -> 67.943947 | AL25: =AL24*(1+C24) -> 122.01726 | AM25: =AM24*(1+D24) -> 97.091194 | AN25: =AN24*(1+E24) -> 162.39964 | AO25: =AO24*(1+F24) -> 182.49446 | AP25: =AP24*(1+G24) -> 122.77018 | AQ25: =AQ24*(1+H24) -> 128.91189 | AR25: =AR24*(1+I24) -> 125.54488 | AV25: 43313 | AW25: =SUMPRODUCT(PRODUCT(B25:B36+1)-1) -> 0.23569642 | AX25: =SUMPRODUCT(PRODUCT(C25:C36+1)-1) -> 0.0686695 | AY25: =SUMPRODUCT(PRODUCT(D25:D36+1)-1) -> 0.53885818 | AZ25: =SUMPRODUCT(PRODUCT(E25:E36+1)-1) -> 0.08357779 | BA25: =SUMPRODUCT(PRODUCT(F25:F36+1)-1) -> -0.026432847 | BB25: =SUMPRODUCT(PRODUCT(G25:G36+1)-1) -> 0.090960338 | BC25: =SUMPRODUCT(PRODUCT(H25:H36+1)-1) -> 0.13124895 | BD25: =SUMPRODUCT(PRODUCT(I25:I36+1)-1) -> 0.18774376 | BH25: 43313 | BI25: =STDEV(B25:B36)*SQRT(12) -> 0.12521416 | BJ25: =STDEV(C25:C36)*SQRT(12) -> 0.0017878377 | BK25: =STDEV(D25:D36)*SQRT(12) -> 0.14646515 | BL25: =STDEV(E25:E36)*SQRT(12) -> 0.21353025 | BM25: =STDEV(F25:F36)*SQRT(12) -> 0.17566899 | BN25: =STDEV(G25:G36)*SQRT(12) -> 0.0099521903 | BO25: =STDEV(H25:H36)*SQRT(12) -> 0.046120449 | BP25: =STDEV(I25:I36)*SQRT(12) -> 0.052749535
A26: 43010 | B26: 0.0299 | C26: 0.0064 | D26: 0.0552 | E26: 0.0027 | F26: -0.0128 | G26: =SUMPRODUCT($B26:$F26,Carteiras!$M$16:$Q$16) -> 0.008655 | H26: =SUMPRODUCT($B26:$F26,Carteiras!$M$17:$Q$17) -> 0.01146 | I26: =SUMPRODUCT($B26:$F26,Carteiras!$M$18:$Q$18) -> 0.017445 | V26: x | X26: Risco | Y26: =STDEV(B5:B951)*SQRT(12) -> 0.16361412 | Z26: =STDEV(C5:C1011)*SQRT(12) -> 0.010928306 | AA26: =STDEV(D5:D1011)*SQRT(12) -> 0.18958047 | AB26: =STDEV(E5:E1011)*SQRT(12) -> 0.25261121 | AC26: =STDEV(F5:F1011)*SQRT(12) -> 0.27495051 | AD26: =STDEV(G5:G1011)*SQRT(12) -> 0.016421044 | AE26: =STDEV(H5:H1011)*SQRT(12) -> 0.074695573 | AF26: =STDEV(I5:I1011)*SQRT(12) -> 0.099252936 | AJ26: 43010 | AK26: =AK25*(1+B25) -> 67.991508 | AL26: =AL25*(1+C25) -> 122.79817 | AM26: =AM25*(1+D25) -> 99.596147 | AN26: =AN25*(1+E25) -> 169.91874 | AO26: =AO25*(1+F25) -> 188.75402 | AP26: =AP25*(1+G25) -> 123.91992 | AQ26: =AQ25*(1+H25) -> 131.38635 | AR26: =AR25*(1+I25) -> 128.30875 | AV26: 43346 | AW26: =SUMPRODUCT(PRODUCT(B26:B37+1)-1) -> 0.23051012 | AX26: =SUMPRODUCT(PRODUCT(C26:C37+1)-1) -> 0.066864315 | AY26: =SUMPRODUCT(PRODUCT(D26:D37+1)-1) -> 0.48695284 | AZ26: =SUMPRODUCT(PRODUCT(E26:E37+1)-1) -> 0.070425312 | BA26: =SUMPRODUCT(PRODUCT(F26:F37+1)-1) -> -0.075285342 | BB26: =SUMPRODUCT(PRODUCT(G26:G37+1)-1) -> 0.086750473 | BC26: =SUMPRODUCT(PRODUCT(H26:H37+1)-1) -> 0.11355644 | BD26: =SUMPRODUCT(PRODUCT(I26:I37+1)-1) -> 0.15586575 | BH26: 43346 | BI26: =STDEV(B26:B37)*SQRT(12) -> 0.12592962 | BJ26: =STDEV(C26:C37)*SQRT(12) -> 0.0017127861 | BK26: =STDEV(D26:D37)*SQRT(12) -> 0.15336597 | BL26: =STDEV(E26:E37)*SQRT(12) -> 0.21144188 | BM26: =STDEV(F26:F37)*SQRT(12) -> 0.17191024 | BN26: =STDEV(G26:G37)*SQRT(12) -> 0.0098255228 | BO26: =STDEV(H26:H37)*SQRT(12) -> 0.045559495 | BP26: =STDEV(I26:I37)*SQRT(12) -> 0.055568958
A27: 43040 | B27: -0.0017 | C27: 0.0057 | D27: 0.0277 | E27: -0.033 | F27: -0.028 | G27: =SUMPRODUCT($B27:$F27,Carteiras!$M$16:$Q$16) -> 0.004865 | H27: =SUMPRODUCT($B27:$F27,Carteiras!$M$17:$Q$17) -> -0.00223 | I27: =SUMPRODUCT($B27:$F27,Carteiras!$M$18:$Q$18) -> -0.000485 | V27: y | X27: Retorno Médio | Y27: =(1+AVERAGE(B5:B954))^12-1 -> 0.025134207 | Z27: =(1+AVERAGE(C5:C954))^12-1 -> 0.072690336 | AA27: =(1+AVERAGE(D5:D954))^12-1 -> 0.2335636 | AB27: =(1+AVERAGE(E5:E954))^12-1 -> 0.25601544 | AC27: =(1+AVERAGE(F5:F954))^12-1 -> 0.31876947 | AD27: =(1+AVERAGE(G5:G954))^12-1 -> 0.088857543 | AE27: =(1+AVERAGE(H5:H954))^12-1 -> 0.15469162 | AF27: =(1+AVERAGE(I5:I954))^12-1 -> 0.19454107 | AJ27: 43040 | AK27: =AK26*(1+B26) -> 70.024454 | AL27: =AL26*(1+C26) -> 123.58408 | AM27: =AM26*(1+D26) -> 105.09385 | AN27: =AN26*(1+E26) -> 170.37752 | AO27: =AO26*(1+F26) -> 186.33797 | AP27: =AP26*(1+G26) -> 124.99245 | AQ27: =AQ26*(1+H26) -> 132.89204 | AR27: =AR26*(1+I26) -> 130.54709 | AV27: 43374 | AW27: =SUMPRODUCT(PRODUCT(B27:B38+1)-1) -> 0.095857738 | AX27: =SUMPRODUCT(PRODUCT(C27:C38+1)-1) -> 0.065804236 | AY27: =SUMPRODUCT(PRODUCT(D27:D38+1)-1) -> 0.21441998 | AZ27: =SUMPRODUCT(PRODUCT(E27:E38+1)-1) -> 0.17162838 | BA27: =SUMPRODUCT(PRODUCT(F27:F38+1)-1) -> 0.052949501 | BB27: =SUMPRODUCT(PRODUCT(G27:G38+1)-1) -> 0.080469083 | BC27: =SUMPRODUCT(PRODUCT(H27:H38+1)-1) -> 0.11312708 | BD27: =SUMPRODUCT(PRODUCT(I27:I38+1)-1) -> 0.12890734 | BH27: 43374 | BI27: =STDEV(B27:B38)*SQRT(12) -> 0.16013011 | BJ27: =STDEV(C27:C38)*SQRT(12) -> 0.0013304135 | BK27: =STDEV(D27:D38)*SQRT(12) -> 0.22842059 | BL27: =STDEV(E27:E38)*SQRT(12) -> 0.22961773 | BM27: =STDEV(F27:F38)*SQRT(12) -> 0.21463805 | BN27: =STDEV(G27:G38)*SQRT(12) -> 0.010439095 | BO27: =STDEV(H27:H38)*SQRT(12) -> 0.045538953 | BP27: =STDEV(I27:I38)*SQRT(12) -> 0.058159874
A28: 43070 | B28: 0.0095 | C28: 0.0057 | D28: 0.0337 | E28: 0.0637 | F28: 0.076 | G28: =SUMPRODUCT($B28:$F28,Carteiras!$M$16:$Q$16) -> 0.01 | H28: =SUMPRODUCT($B28:$F28,Carteiras!$M$17:$Q$17) -> 0.029335 | I28: =SUMPRODUCT($B28:$F28,Carteiras!$M$18:$Q$18) -> 0.03847 | AJ28: 43070 | AK28: =AK27*(1+B27) -> 69.905412 | AL28: =AL27*(1+C27) -> 124.28851 | AM28: =AM27*(1+D27) -> 108.00495 | AN28: =AN27*(1+E27) -> 164.75506 | AO28: =AO27*(1+F27) -> 181.12051 | AP28: =AP27*(1+G27) -> 125.60054 | AQ28: =AQ27*(1+H27) -> 132.59569 | AR28: =AR27*(1+I27) -> 130.48378 | AV28: 43405 | AW28: =SUMPRODUCT(PRODUCT(B28:B39+1)-1) -> 0.13493671 | AX28: =SUMPRODUCT(PRODUCT(C28:C39+1)-1) -> 0.064956425 | AY28: =SUMPRODUCT(PRODUCT(D28:D39+1)-1) -> 0.24738905 | AZ28: =SUMPRODUCT(PRODUCT(E28:E39+1)-1) -> 0.2445674 | BA28: =SUMPRODUCT(PRODUCT(F28:F39+1)-1) -> 0.14297018 | BB28: =SUMPRODUCT(PRODUCT(G28:G39+1)-1) -> 0.084431336 | BC28: =SUMPRODUCT(PRODUCT(H28:H39+1)-1) -> 0.14331562 | BD28: =SUMPRODUCT(PRODUCT(I28:I39+1)-1) -> 0.17371283 | BH28: 43405 | BI28: =STDEV(B28:B39)*SQRT(12) -> 0.16157273 | BJ28: =STDEV(C28:C39)*SQRT(12) -> 0.0013249357 | BK28: =STDEV(D28:D39)*SQRT(12) -> 0.23135154 | BL28: =STDEV(E28:E39)*SQRT(12) -> 0.22361898 | BM28: =STDEV(F28:F39)*SQRT(12) -> 0.21633312 | BN28: =STDEV(G28:G39)*SQRT(12) -> 0.010469617 | BO28: =STDEV(H28:H39)*SQRT(12) -> 0.046261142 | BP28: =STDEV(I28:I39)*SQRT(12) -> 0.063437555
A29: 43102 | B29: -0.0431 | C29: 0.0058 | D29: 0.008 | E29: 0.1108 | F29: 0.0401 | G29: =SUMPRODUCT($B29:$F29,Carteiras!$M$16:$Q$16) -> 0.01116 | H29: =SUMPRODUCT($B29:$F29,Carteiras!$M$17:$Q$17) -> 0.02458 | I29: =SUMPRODUCT($B29:$F29,Carteiras!$M$18:$Q$18) -> 0.01711 | AJ29: 43102 | AK29: =AK28*(1+B28) -> 70.569514 | AL29: =AL28*(1+C28) -> 124.99695 | AM29: =AM28*(1+D28) -> 111.64472 | AN29: =AN28*(1+E28) -> 175.24996 | AO29: =AO28*(1+F28) -> 194.88567 | AP29: =AP28*(1+G28) -> 126.85655 | AQ29: =AQ28*(1+H28) -> 136.48538 | AR29: =AR28*(1+I28) -> 135.50349 | AV29: 43437 | AW29: =SUMPRODUCT(PRODUCT(B29:B40+1)-1) -> 0.12774147 | AX29: =SUMPRODUCT(PRODUCT(C29:C40+1)-1) -> 0.064109288 | AY29: =SUMPRODUCT(PRODUCT(D29:D40+1)-1) -> 0.09775546 | AZ29: =SUMPRODUCT(PRODUCT(E29:E40+1)-1) -> 0.14605036 | BA29: =SUMPRODUCT(PRODUCT(F29:F40+1)-1) -> 0.075305498 | BB29: =SUMPRODUCT(PRODUCT(G29:G40+1)-1) -> 0.072481117 | BC29: =SUMPRODUCT(PRODUCT(H29:H40+1)-1) -> 0.097214674 | BD29: =SUMPRODUCT(PRODUCT(I29:I40+1)-1) -> 0.10436174 | BH29: 43437 | BI29: =STDEV(B29:B40)*SQRT(12) -> 0.16179045 | BJ29: =STDEV(C29:C40)*SQRT(12) -> 0.0012745766 | BK29: =STDEV(D29:D40)*SQRT(12) -> 0.25568669 | BL29: =STDEV(E29:E40)*SQRT(12) -> 0.22163855 | BM29: =STDEV(F29:F40)*SQRT(12) -> 0.20518172 | BN29: =STDEV(G29:G40)*SQRT(12) -> 0.012463424 | BO29: =STDEV(H29:H40)*SQRT(12) -> 0.047222763 | BP29: =STDEV(I29:I40)*SQRT(12) -> 0.066770547
A30: 43132 | B30: 0.0164 | C30: 0.0046 | D30: -0.018 | E30: 0.0061 | F30: -0.0065 | G30: =SUMPRODUCT($B30:$F30,Carteiras!$M$16:$Q$16) -> 0.003545 | H30: =SUMPRODUCT($B30:$F30,Carteiras!$M$17:$Q$17) -> 0.00036 | I30: =SUMPRODUCT($B30:$F30,Carteiras!$M$18:$Q$18) -> -0.004255 | AJ30: 43132 | AK30: =AK29*(1+B29) -> 67.527968 | AL30: =AL29*(1+C29) -> 125.72193 | AM30: =AM29*(1+D29) -> 112.53788 | AN30: =AN29*(1+E29) -> 194.66766 | AO30: =AO29*(1+F29) -> 202.70058 | AP30: =AP29*(1+G29) -> 128.27226 | AQ30: =AQ29*(1+H29) -> 139.84019 | AR30: =AR29*(1+I29) -> 137.82195 | AV30: 43467 | AW30: =SUMPRODUCT(PRODUCT(B30:B41+1)-1) -> 0.10652781 | AX30: =SUMPRODUCT(PRODUCT(C30:C41+1)-1) -> 0.063686099 | AY30: =SUMPRODUCT(PRODUCT(D30:D41+1)-1) -> 0.10831918 | AZ30: =SUMPRODUCT(PRODUCT(E30:E41+1)-1) -> 0.14635988 | BA30: =SUMPRODUCT(PRODUCT(F30:F41+1)-1) -> 0.13185699 | BB30: =SUMPRODUCT(PRODUCT(G30:G41+1)-1) -> 0.072629607 | BC30: =SUMPRODUCT(PRODUCT(H30:H41+1)-1) -> 0.1064297 | BD30: =SUMPRODUCT(PRODUCT(I30:I41+1)-1) -> 0.12329239 | BH30: 43467 | BI30: =STDEV(B30:B41)*SQRT(12) -> 0.16919736 | BJ30: =STDEV(C30:C41)*SQRT(12) -> 0.001119659 | BK30: =STDEV(D30:D41)*SQRT(12) -> 0.25577376 | BL30: =STDEV(E30:E41)*SQRT(12) -> 0.22178269 | BM30: =STDEV(F30:F41)*SQRT(12) -> 0.22127224 | BN30: =STDEV(G30:G41)*SQRT(12) -> 0.012529055 | BO30: =STDEV(H30:H41)*SQRT(12) -> 0.051168464 | BP30: =STDEV(I30:I41)*SQRT(12) -> 0.071349566
A31: 43160 | B31: 0.0141 | C31: 0.0053 | D31: -0.0102 | E31: -0.0008 | F31: 0.0012 | G31: =SUMPRODUCT($B31:$F31,Carteiras!$M$16:$Q$16) -> 0.00422 | H31: =SUMPRODUCT($B31:$F31,Carteiras!$M$17:$Q$17) -> 0.001885 | I31: =SUMPRODUCT($B31:$F31,Carteiras!$M$18:$Q$18) -> -5e-06 | AJ31: 43160 | AK31: =AK30*(1+B30) -> 68.635426 | AL31: =AL30*(1+C30) -> 126.30025 | AM31: =AM30*(1+D30) -> 110.5122 | AN31: =AN30*(1+E30) -> 195.85513 | AO31: =AO30*(1+F30) -> 201.38303 | AP31: =AP30*(1+G30) -> 128.72699 | AQ31: =AQ30*(1+H30) -> 139.89054 | AR31: =AR30*(1+I30) -> 137.23552 | AV31: 43497 | AW31: =SUMPRODUCT(PRODUCT(B31:B42+1)-1) -> 0.11828549 | AX31: =SUMPRODUCT(PRODUCT(C31:C42+1)-1) -> 0.064003744 | AY31: =SUMPRODUCT(PRODUCT(D31:D42+1)-1) -> 0.20131867 | AZ31: =SUMPRODUCT(PRODUCT(E31:E42+1)-1) -> 0.113317 | BA31: =SUMPRODUCT(PRODUCT(F31:F42+1)-1) -> 0.11613518 | BB31: =SUMPRODUCT(PRODUCT(G31:G42+1)-1) -> 0.075771998 | BC31: =SUMPRODUCT(PRODUCT(H31:H42+1)-1) -> 0.11376269 | BD31: =SUMPRODUCT(PRODUCT(I31:I42+1)-1) -> 0.14617574 | BH31: 43497 | BI31: =STDEV(B31:B42)*SQRT(12) -> 0.17001532 | BJ31: =STDEV(C31:C42)*SQRT(12) -> 0.00098903075 | BK31: =STDEV(D31:D42)*SQRT(12) -> 0.25878434 | BL31: =STDEV(E31:E42)*SQRT(12) -> 0.22468907 | BM31: =STDEV(F31:F42)*SQRT(12) -> 0.2229706 | BN31: =STDEV(G31:G42)*SQRT(12) -> 0.012277367 | BO31: =STDEV(H31:H42)*SQRT(12) -> 0.05043322 | BP31: =STDEV(I31:I42)*SQRT(12) -> 0.069817846
A32: 43192 | B32: 0.0588 | C32: 0.0052 | D32: 0.0648 | E32: 0.0091 | F32: 0.0217 | G32: =SUMPRODUCT($B32:$F32,Carteiras!$M$16:$Q$16) -> 0.008375 | H32: =SUMPRODUCT($B32:$F32,Carteiras!$M$17:$Q$17) -> 0.01988 | I32: =SUMPRODUCT($B32:$F32,Carteiras!$M$18:$Q$18) -> 0.033585 | AJ32: 43192 | AK32: =AK31*(1+B31) -> 69.603186 | AL32: =AL31*(1+C31) -> 126.96964 | AM32: =AM31*(1+D31) -> 109.38497 | AN32: =AN31*(1+E31) -> 195.69845 | AO32: =AO31*(1+F31) -> 201.62469 | AP32: =AP31*(1+G31) -> 129.27022 | AQ32: =AQ31*(1+H31) -> 140.15423 | AR32: =AR31*(1+I31) -> 137.23483 | AV32: 43525 | AW32: =SUMPRODUCT(PRODUCT(B32:B43+1)-1) -> 0.15103677 | AX32: =SUMPRODUCT(PRODUCT(C32:C43+1)-1) -> 0.063368707 | AY32: =SUMPRODUCT(PRODUCT(D32:D43+1)-1) -> 0.28894769 | AZ32: =SUMPRODUCT(PRODUCT(E32:E43+1)-1) -> 0.11376269 | BA32: =SUMPRODUCT(PRODUCT(F32:F43+1)-1) -> 0.11858773 | BB32: =SUMPRODUCT(PRODUCT(G32:G43+1)-1) -> 0.079082165 | BC32: =SUMPRODUCT(PRODUCT(H32:H43+1)-1) -> 0.12755292 | BD32: =SUMPRODUCT(PRODUCT(I32:I43+1)-1) -> 0.17501367 | BH32: 43525 | BI32: =STDEV(B32:B43)*SQRT(12) -> 0.17326915 | BJ32: =STDEV(C32:C43)*SQRT(12) -> 0.0010887858 | BK32: =STDEV(D32:D43)*SQRT(12) -> 0.26026387 | BL32: =STDEV(E32:E43)*SQRT(12) -> 0.2246667 | BM32: =STDEV(F32:F43)*SQRT(12) -> 0.22287505 | BN32: =STDEV(G32:G43)*SQRT(12) -> 0.012146365 | BO32: =STDEV(H32:H43)*SQRT(12) -> 0.050016989 | BP32: =STDEV(I32:I43)*SQRT(12) -> 0.0697818
A33: 43222 | B33: 0.0566 | C33: 0.0052 | D33: 0.1001 | E33: -0.1095 | F33: -0.1118 | G33: =SUMPRODUCT($B33:$F33,Carteiras!$M$16:$Q$16) -> 0.00421 | H33: =SUMPRODUCT($B33:$F33,Carteiras!$M$17:$Q$17) -> -0.01275 | I33: =SUMPRODUCT($B33:$F33,Carteiras!$M$18:$Q$18) -> -0.002025 | AJ33: 43222 | AK33: =AK32*(1+B32) -> 73.695853 | AL33: =AL32*(1+C32) -> 127.62989 | AM33: =AM32*(1+D32) -> 116.47312 | AN33: =AN32*(1+E32) -> 197.4793 | AO33: =AO32*(1+F32) -> 205.99994 | AP33: =AP32*(1+G32) -> 130.35286 | AQ33: =AQ32*(1+H32) -> 142.9405 | AR33: =AR32*(1+I32) -> 141.84387 | AV33: 43556 | AW33: =SUMPRODUCT(PRODUCT(B33:B44+1)-1) -> 0.085157638 | AX33: =SUMPRODUCT(PRODUCT(C33:C44+1)-1) -> 0.063368707 | AY33: =SUMPRODUCT(PRODUCT(D33:D44+1)-1) -> 0.25868502 | AZ33: =SUMPRODUCT(PRODUCT(E33:E44+1)-1) -> 0.11663236 | BA33: =SUMPRODUCT(PRODUCT(F33:F44+1)-1) -> 0.11070495 | BB33: =SUMPRODUCT(PRODUCT(G33:G44+1)-1) -> 0.077883631 | BC33: =SUMPRODUCT(PRODUCT(H33:H44+1)-1) -> 0.11929428 | BD33: =SUMPRODUCT(PRODUCT(I33:I44+1)-1) -> 0.15729044 | BH33: 43556 | BI33: =STDEV(B33:B44)*SQRT(12) -> 0.16622983 | BJ33: =STDEV(C33:C44)*SQRT(12) -> 0.0010887858 | BK33: =STDEV(D33:D44)*SQRT(12) -> 0.25717434 | BL33: =STDEV(E33:E44)*SQRT(12) -> 0.2246586 | BM33: =STDEV(F33:F44)*SQRT(12) -> 0.22262351 | BN33: =STDEV(G33:G44)*SQRT(12) -> 0.011995208 | BO33: =STDEV(H33:H44)*SQRT(12) -> 0.04897862 | BP33: =STDEV(I33:I44)*SQRT(12) -> 0.066608398
A34: 43252 | B34: 0.0384 | C34: 0.0052 | D34: 0.0338 | E34: -0.0502 | F34: -0.0368 | G34: =SUMPRODUCT($B34:$F34,Carteiras!$M$16:$Q$16) -> 0.00386 | H34: =SUMPRODUCT($B34:$F34,Carteiras!$M$17:$Q$17) -> -0.00346 | I34: =SUMPRODUCT($B34:$F34,Carteiras!$M$18:$Q$18) -> 0.00173 | AJ34: 43252 | AK34: =AK33*(1+B33) -> 77.867039 | AL34: =AL33*(1+C33) -> 128.29356 | AM34: =AM33*(1+D33) -> 128.13208 | AN34: =AN33*(1+E33) -> 175.85532 | AO34: =AO33*(1+F33) -> 182.96915 | AP34: =AP33*(1+G33) -> 130.90164 | AQ34: =AQ33*(1+H33) -> 141.118 | AR34: =AR33*(1+I33) -> 141.55663 | AV34: 43587 | AW34: =SUMPRODUCT(PRODUCT(B34:B45+1)-1) -> 0.026000833 | AX34: =SUMPRODUCT(PRODUCT(C34:C45+1)-1) -> 0.063580281 | AY34: =SUMPRODUCT(PRODUCT(D34:D45+1)-1) -> 0.071501249 | AZ34: =SUMPRODUCT(PRODUCT(E34:E45+1)-1) -> 0.26346857 | BA34: =SUMPRODUCT(PRODUCT(F34:F45+1)-1) -> 0.27352165 | BB34: =SUMPRODUCT(PRODUCT(G34:G45+1)-1) -> 0.075581263 | BC34: =SUMPRODUCT(PRODUCT(H34:H45+1)-1) -> 0.13037669 | BD34: =SUMPRODUCT(PRODUCT(I34:I45+1)-1) -> 0.14583901 | BH34: 43587 | BI34: =STDEV(B34:B45)*SQRT(12) -> 0.15757492 | BJ34: =STDEV(C34:C45)*SQRT(12) -> 0.0011200649 | BK34: =STDEV(D34:D45)*SQRT(12) -> 0.25496728 | BL34: =STDEV(E34:E45)*SQRT(12) -> 0.18264424 | BM34: =STDEV(F34:F45)*SQRT(12) -> 0.17811184 | BN34: =STDEV(G34:G45)*SQRT(12) -> 0.01257578 | BO34: =STDEV(H34:H45)*SQRT(12) -> 0.044937238 | BP34: =STDEV(I34:I45)*SQRT(12) -> 0.069608395
A35: 43283 | B35: -0.0349 | C35: 0.0054 | D35: 0.0052 | E35: 0.0867 | F35: 0.0519 | G35: =SUMPRODUCT($B35:$F35,Carteiras!$M$16:$Q$16) -> 0.009455 | H35: =SUMPRODUCT($B35:$F35,Carteiras!$M$17:$Q$17) -> 0.022525 | I35: =SUMPRODUCT($B35:$F35,Carteiras!$M$18:$Q$18) -> 0.019325 | AJ35: 43283 | AK35: =AK34*(1+B34) -> 80.857133 | AL35: =AL34*(1+C34) -> 128.96069 | AM35: =AM34*(1+D34) -> 132.46294 | AN35: =AN34*(1+E34) -> 167.02738 | AO35: =AO34*(1+F34) -> 176.23589 | AP35: =AP34*(1+G34) -> 131.40692 | AQ35: =AQ34*(1+H34) -> 140.62974 | AR35: =AR34*(1+I34) -> 141.80152 | AV35: 43619 | AW35: =SUMPRODUCT(PRODUCT(B35:B46+1)-1) -> -0.033677952 | AX35: =SUMPRODUCT(PRODUCT(C35:C46+1)-1) -> 0.063051242 | AY35: =SUMPRODUCT(PRODUCT(D35:D46+1)-1) -> 0.078341941 | AZ35: =SUMPRODUCT(PRODUCT(E35:E46+1)-1) -> 0.38026426 | BA35: =SUMPRODUCT(PRODUCT(F35:F46+1)-1) -> 0.41499467 | BB35: =SUMPRODUCT(PRODUCT(G35:G46+1)-1) -> 0.080156336 | BC35: =SUMPRODUCT(PRODUCT(H35:H46+1)-1) -> 0.16093476 | BD35: =SUMPRODUCT(PRODUCT(I35:I46+1)-1) -> 0.18279141 | BH35: 43619 | BI35: =STDEV(B35:B46)*SQRT(12) -> 0.15435711 | BJ35: =STDEV(C35:C46)*SQRT(12) -> 0.0012041595 | BK35: =STDEV(D35:D46)*SQRT(12) -> 0.25577106 | BL35: =STDEV(E35:E46)*SQRT(12) -> 0.16566831 | BM35: =STDEV(F35:F46)*SQRT(12) -> 0.17192597 | BN35: =STDEV(G35:G46)*SQRT(12) -> 0.012471946 | BO35: =STDEV(H35:H46)*SQRT(12) -> 0.043976204 | BP35: =STDEV(I35:I46)*SQRT(12) -> 0.072067798
A36: 43313 | B36: 0.0759 | C36: 0.0057 | D36: 0.1221 | E36: -0.0305 | F36: -0.0416 | G36: =SUMPRODUCT($B36:$F36,Carteiras!$M$16:$Q$16) -> 0.00971 | H36: =SUMPRODUCT($B36:$F36,Carteiras!$M$17:$Q$17) -> 0.014145 | I36: =SUMPRODUCT($B36:$F36,Carteiras!$M$18:$Q$18) -> 0.03164 | AJ36: 43313 | AK36: =AK35*(1+B35) -> 78.035219 | AL36: =AL35*(1+C35) -> 129.65708 | AM36: =AM35*(1+D35) -> 133.15175 | AN36: =AN35*(1+E35) -> 181.50866 | AO36: =AO35*(1+F35) -> 185.38253 | AP36: =AP35*(1+G35) -> 132.64937 | AQ36: =AQ35*(1+H35) -> 143.79742 | AR36: =AR35*(1+I35) -> 144.54184 | AV36: 43647 | AW36: =SUMPRODUCT(PRODUCT(B36:B47+1)-1) -> -0.010949208 | AX36: =SUMPRODUCT(PRODUCT(C36:C47+1)-1) -> 0.063368444 | AY36: =SUMPRODUCT(PRODUCT(D36:D47+1)-1) -> 0.085422181 | AZ36: =SUMPRODUCT(PRODUCT(E36:E47+1)-1) -> 0.28157415 | BA36: =SUMPRODUCT(PRODUCT(F36:F47+1)-1) -> 0.43154038 | BB36: =SUMPRODUCT(PRODUCT(G36:G47+1)-1) -> 0.076641257 | BC36: =SUMPRODUCT(PRODUCT(H36:H47+1)-1) -> 0.15237982 | BD36: =SUMPRODUCT(PRODUCT(I36:I47+1)-1) -> 0.18758373 | BH36: 43647 | BI36: =STDEV(B36:B47)*SQRT(12) -> 0.15069392 | BJ36: =STDEV(C36:C47)*SQRT(12) -> 0.0013156402 | BK36: =STDEV(D36:D47)*SQRT(12) -> 0.255753 | BL36: =STDEV(E36:E47)*SQRT(12) -> 0.1535258 | BM36: =STDEV(F36:F47)*SQRT(12) -> 0.17402849 | BN36: =STDEV(G36:G47)*SQRT(12) -> 0.012034032 | BO36: =STDEV(H36:H47)*SQRT(12) -> 0.042746809 | BP36: =STDEV(I36:I47)*SQRT(12) -> 0.072499926
A37: 43346 | B37: -0.0035 | C37: 0.0047 | D37: -0.0088 | E37: 0.0336 | F37: -0.0176 | G37: =SUMPRODUCT($B37:$F37,Carteiras!$M$16:$Q$16) -> 0.00547 | H37: =SUMPRODUCT($B37:$F37,Carteiras!$M$17:$Q$17) -> 0.003255 | I37: =SUMPRODUCT($B37:$F37,Carteiras!$M$18:$Q$18) -> -0.005415 | AJ37: 43346 | AK37: =AK36*(1+B36) -> 83.958092 | AL37: =AL36*(1+C36) -> 130.39612 | AM37: =AM36*(1+D36) -> 149.40958 | AN37: =AN36*(1+E36) -> 175.97264 | AO37: =AO36*(1+F36) -> 177.67062 | AP37: =AP36*(1+G36) -> 133.9374 | AQ37: =AQ36*(1+H36) -> 145.83144 | AR37: =AR36*(1+I36) -> 149.11514 | AV37: 43678 | AW37: =SUMPRODUCT(PRODUCT(B37:B48+1)-1) -> -0.0045142647 | AX37: =SUMPRODUCT(PRODUCT(C37:C48+1)-1) -> 0.062628305 | AY37: =SUMPRODUCT(PRODUCT(D37:D48+1)-1) -> 0.030962446 | AZ37: =SUMPRODUCT(PRODUCT(E37:E48+1)-1) -> 0.31686867 | BA37: =SUMPRODUCT(PRODUCT(F37:F48+1)-1) -> 0.51055591 | BB37: =SUMPRODUCT(PRODUCT(G37:G48+1)-1) -> 0.07439139 | BC37: =SUMPRODUCT(PRODUCT(H37:H48+1)-1) -> 0.15635121 | BD37: =SUMPRODUCT(PRODUCT(I37:I48+1)-1) -> 0.1885507 | BH37: 43678 | BI37: =STDEV(B37:B48)*SQRT(12) -> 0.15465282 | BJ37: =STDEV(C37:C48)*SQRT(12) -> 0.0011642399 | BK37: =STDEV(D37:D48)*SQRT(12) -> 0.23396084 | BL37: =STDEV(E37:E48)*SQRT(12) -> 0.14573696 | BM37: =STDEV(F37:F48)*SQRT(12) -> 0.15700976 | BN37: =STDEV(G37:G48)*SQRT(12) -> 0.011533062 | BO37: =STDEV(H37:H48)*SQRT(12) -> 0.043083397 | BP37: =STDEV(I37:I48)*SQRT(12) -> 0.072719469
A38: 43374 | B38: -0.0828 | C38: 0.0054 | D38: -0.1382 | E38: 0.0975 | F38: 0.1241 | G38: =SUMPRODUCT($B38:$F38,Carteiras!$M$16:$Q$16) -> 0.002825 | H38: =SUMPRODUCT($B38:$F38,Carteiras!$M$17:$Q$17) -> 0.01107 | I38: =SUMPRODUCT($B38:$F38,Carteiras!$M$18:$Q$18) -> -0.006285 | AJ38: 43374 | AK38: =AK37*(1+B37) -> 83.664239 | AL38: =AL37*(1+C37) -> 131.00898 | AM38: =AM37*(1+D37) -> 148.09477 | AN38: =AN37*(1+E37) -> 181.88532 | AO38: =AO37*(1+F37) -> 174.54361 | AP38: =AP37*(1+G37) -> 134.67004 | AQ38: =AQ37*(1+H37) -> 146.30612 | AR38: =AR37*(1+I37) -> 148.30768 | AV38: 43710 | AW38: =SUMPRODUCT(PRODUCT(B38:B49+1)-1) -> -1.8844958e-05 | AX38: =SUMPRODUCT(PRODUCT(C38:C49+1)-1) -> 0.062522539 | AY38: =SUMPRODUCT(PRODUCT(D38:D49+1)-1) -> 0.06622236 | AZ38: =SUMPRODUCT(PRODUCT(E38:E49+1)-1) -> 0.31839754 | BA38: =SUMPRODUCT(PRODUCT(F38:F49+1)-1) -> 0.55560812 | BB38: =SUMPRODUCT(PRODUCT(G38:G49+1)-1) -> 0.07617052 | BC38: =SUMPRODUCT(PRODUCT(H38:H49+1)-1) -> 0.16768703 | BD38: =SUMPRODUCT(PRODUCT(I38:I49+1)-1) -> 0.2117879 | BH38: 43710 | BI38: =STDEV(B38:B49)*SQRT(12) -> 0.15458998 | BJ38: =STDEV(C38:C49)*SQRT(12) -> 0.0012030265 | BK38: =STDEV(D38:D49)*SQRT(12) -> 0.23427874 | BL38: =STDEV(E38:E49)*SQRT(12) -> 0.14582833 | BM38: =STDEV(F38:F49)*SQRT(12) -> 0.14863572 | BN38: =STDEV(G38:G49)*SQRT(12) -> 0.011569327 | BO38: =STDEV(H38:H49)*SQRT(12) -> 0.041951149 | BP38: =STDEV(I38:I49)*SQRT(12) -> 0.069374898
